Workbook

Sheet Hora Máx.
C2: MUNICIPIO: | E2: Monterrey, N.L.
C3: INTERSECCION: | E3: Int. 03 Av. Fernando García Roel - Ahuehuetes - Los Nogales
C4: PERIODO: | E4: 0.29166667 | F4: A: | G4: 0.41666667 | H4: HRS
C5: INTERVALOS DE: | E5: 0.010416667 | F5: HORAS | G5: FECHA:
A8: LAPSO | E8: TOTAL | H8: TOTAL POR HORAS
A9: H:MIN | B9: H:MIN
A10: =E4 -> 0.29166667 | B10: =A10+$E$5 -> 0.30208333 | E10: =SUM('1:12'!Q10) -> #REF!
A11: =IF(B10>=$G$4,"",B10) -> 0.30208333 | B11: =IF(A11="","",A11+$E$5) -> 0.3125 | E11: =SUM('1:12'!Q11) -> #REF!
A12: =IF(B11>=$G$4,"",B11) -> 0.3125 | B12: =IF(A12="","",A12+$E$5) -> 0.32291667 | E12: =SUM('1:12'!Q12) -> #REF!
A13: =IF(B12>=$G$4,"",B12) -> 0.32291667 | B13: =IF(A13="","",A13+$E$5) -> 0.33333333 | E13: =SUM('1:12'!Q13) -> #REF! | I13: =SUM(E10:E13) -> #REF!
A15: =IF(B13>=$G$4,"",B13) -> 0.33333333 | B15: =IF(A15="","",A15+$E$5) -> 0.34375 | E15: =SUM('1:12'!Q15) -> #REF! | I15: =SUM(E11:E13,E15) -> #REF!
A16: =IF(B15>=$G$4,"",B15) -> 0.34375 | B16: =IF(A16="","",A16+$E$5) -> 0.35416667 | E16: =SUM('1:12'!Q16) -> #REF! | I16: =SUM(E12:E13,E15:E16) -> #REF!
A17: =IF(B16>=$G$4,"",B16) -> 0.35416667 | B17: =IF(A17="","",A17+$E$5) -> 0.36458333 | E17: =SUM('1:12'!Q17) -> #REF! | I17: =SUM(E13,E15:E17) -> #REF!
A18: =IF(B17>=$G$4,"",B17) -> 0.36458333 | B18: =IF(A18="","",A18+$E$5) -> 0.375 | E18: =SUM('1:12'!Q18) -> #REF! | I18: =SUM(E15:E18) -> #REF!
A20: =IF(B18>=$G$4,"",B18) -> 0.375 | B20: =IF(A20="","",A20+$E$5) -> 0.38541667 | E20: =SUM('1:12'!Q20) -> #REF! | I20: =SUM(E16:E18,E20) -> #REF!
A21: =IF(B20>=$G$4,"",B20) -> 0.38541667 | B21: =IF(A21="","",A21+$E$5) -> 0.39583333 | E21: =SUM('1:12'!Q21) -> #REF! | I21: =SUM(E17:E18,E20:E21) -> #REF!
A22: =IF(B21>=$G$4,"",B21) -> 0.39583333 | B22: =IF(A22="","",A22+$E$5) -> 0.40625 | E22: =SUM('1:12'!Q22) -> #REF! | I22: =SUM(E18,E20:E22) -> #REF!
A23: =IF(B22>=$G$4,"",B22) -> 0.40625 | B23: =IF(A23="","",A23+$E$5) -> 0.41666667 | E23: =SUM('1:12'!Q23) -> #REF! | I23: =SUM(E20:E23) -> #REF!
G29: HORA MAX: | H29: =IF($I$31=I13,A10,IF($I$31=I15,A11,IF($I$31=I16,A12,IF($I$31=I17,A13,IF($I$31=I18,A15,IF($I$31=I20,A16,IF($I$31=I21,A17,IF($I$31=I22,A18,A20)))))))) -> #REF! | I29: =IF($I$31=I13,B13,IF($I$31=I15,B15,IF($I$31=I16,B16,IF($I$31=I17,B17,IF($I$31=I18,B18,IF($I$31=I20,B20,IF($I$31=I21,B21,IF($I$31=I22,B22,B23)))))))) -> #REF!
G31: TOTAL DE VEHICULOS: | I31: =MAX(I10:I13,I15:I18,I20:I23) -> #REF!

Sheet 1
C2: MUNICIPIO: | E2: ='Hora Máx.'!E2 -> Monterrey, N.L.
C3: INTERSECCION: | E3: ='Hora Máx.'!E3 -> Int. 03 Av. Fernando García Roel - Ahuehuetes - Los Nogales | K3: FECHA: | L3: ='Hora Máx.'!$H$5
C4: SENTIDO CIRCULACION: | E4: mov. 1 | I4: PERIODO: | J4: ='Hora Máx.'!$E$4 -> 0.29166667 | K4: A: | L4: ='Hora Máx.'!$G$4 -> 0.41666667
C5: ESTADO DEL TIEMPO: | E5: Soleado | I5: PAVIMENTO: | J5: Regular y Seco
A8: LAPSO | C8: AUTOMOVILES | D8: CAMIONETAS | E8: BTR | F8: B | G8: BICICLETAS | H8: C-2 | I8: C-3 | J8: C-4 | K8: C-5 | L8: C-6 | M8: C-7 | N8: C-8 | O8: C-9 | P8: MOTOS | Q8: TOTAL
A9: H:MIN | B9: H:MIN
A10: ='Hora Máx.'!A10 -> 0.29166667 | B10: ='Hora Máx.'!B10 -> 0.30208333 | C10: 11 | Q10: =SUM(C10:P10) -> 11 | R10: =IF(A10='Hora Máx.'!$H$29,(Q10+Q11+Q12+Q13)/(MAX(Q10:Q13)*4),"") -> #REF!
A11: ='Hora Máx.'!A11 -> 0.30208333 | B11: ='Hora Máx.'!B11 -> 0.3125 | C11: 10 | Q11: =SUM(C11:P11) -> 10 | R11: =IF(A11='Hora Máx.'!$H$29,(Q11+Q12+Q13+Q15)/(MAX(Q11:Q13,Q15)*4),"") -> #REF!
A12: ='Hora Máx.'!A12 -> 0.3125 | B12: ='Hora Máx.'!B12 -> 0.32291667 | C12: 8 | Q12: =SUM(C12:P12) -> 8 | R12: =IF(A12='Hora Máx.'!$H$29,(Q12+Q13+Q15+Q16)/(MAX(Q12,Q13,Q15,Q16)*4),"") -> #REF!
A13: ='Hora Máx.'!A13 -> 0.32291667 | B13: ='Hora Máx.'!B13 -> 0.33333333 | C13: 12 | Q13: =SUM(C13:P13) -> 12 | R13: =IF(A13='Hora Máx.'!$H$29,(Q13+Q15+Q16+Q17)/(MAX(Q13,Q15:Q17)*4),"") -> #REF!
A15: ='Hora Máx.'!A15 -> 0.33333333 | B15: ='Hora Máx.'!B15 -> 0.34375 | C15: 5 | Q15: =SUM(C15:P15) -> 5 | R15: =IF(A15='Hora Máx.'!$H$29,(Q15+Q16+Q17+Q18)/(MAX(Q15:Q18)*4),"") -> #REF!
A16: ='Hora Máx.'!A16 -> 0.34375 | B16: ='Hora Máx.'!B16 -> 0.35416667 | C16: 7 | Q16: =SUM(C16:P16) -> 7 | R16: =IF(A16='Hora Máx.'!$H$29,(Q16+Q17+Q18+Q20)/(MAX(Q16:Q18,Q20)*4),"") -> #REF!
A17: ='Hora Máx.'!A17 -> 0.35416667 | B17: ='Hora Máx.'!B17 -> 0.36458333 | C17: 4 | Q17: =SUM(C17:P17) -> 4 | R17: =IF(A17='Hora Máx.'!$H$29,(Q17+Q18+Q20+Q21)/(MAX(Q17,Q18,Q20,Q21)*4),"") -> #REF!
A18: ='Hora Máx.'!A18 -> 0.36458333 | B18: ='Hora Máx.'!B18 -> 0.375 | C18: 5 | Q18: =SUM(C18:P18) -> 5 | R18: =IF(A18='Hora Máx.'!$H$29,(Q18+Q20+Q21+Q22)/(MAX(Q18,Q20:Q22)*4),"") -> #REF!
A20: ='Hora Máx.'!A20 -> 0.375 | B20: ='Hora Máx.'!B20 -> 0.38541667 | C20: 3 | Q20: =SUM(C20:P20) -> 3 | R20: =IF(A20='Hora Máx.'!$H$29,(Q20+Q21+Q22+Q23)/(MAX(Q20:Q23)*4),"") -> #REF!
A21: ='Hora Máx.'!A21 -> 0.38541667 | B21: ='Hora Máx.'!B21 -> 0.39583333 | C21: 7 | Q21: =SUM(C21:P21) -> 7
A22: ='Hora Máx.'!A22 -> 0.39583333 | B22: ='Hora Máx.'!B22 -> 0.40625 | C22: 7 | Q22: =SUM(C22:P22) -> 7
A23: ='Hora Máx.'!A23 -> 0.40625 | B23: ='Hora Máx.'!B23 -> 0.41666667 | C23: 4 | Q23: =SUM(C23:P23) -> 4

Sheet 2
C2: MUNICIPIO: | E2: ='Hora Máx.'!E2 -> Monterrey, N.L.
C3: INTERSECCION: | E3: ='Hora Máx.'!E3 -> Int. 03 Av. Fernando García Roel - Ahuehuetes - Los Nogales | K3: FECHA: | L3: ='Hora Máx.'!$H$5
C4: SENTIDO CIRCULACION: | E4: mov. 2 | I4: PERIODO: | J4: ='Hora Máx.'!$E$4 -> 0.29166667 | K4: A: | L4: ='Hora Máx.'!$G$4 -> 0.41666667
C5: ESTADO DEL TIEMPO: | E5: Soleado | I5: PAVIMENTO: | J5: Regular y Seco
A8: LAPSO | C8: AUTOMOVILES | D8: CAMIONETAS | E8: BTR | F8: B | G8: BICICLETAS | H8: C-2 | I8: C-3 | J8: C-4 | K8: C-5 | L8: C-6 | M8: C-7 | N8: C-8 | O8: C-9 | P8: MOTOS | Q8: TOTAL
A9: H:MIN | B9: H:MIN
A10: ='Hora Máx.'!A10 -> 0.29166667 | B10: ='Hora Máx.'!B10 -> 0.30208333 | C10: 4 | Q10: =SUM(C10:P10) -> 4 | R10: =IF(A10='Hora Máx.'!$H$29,(Q10+Q11+Q12+Q13)/(MAX(Q10:Q13)*4),"") -> #REF!
A11: ='Hora Máx.'!A11 -> 0.30208333 | B11: ='Hora Máx.'!B11 -> 0.3125 | C11: 11 | Q11: =SUM(C11:P11) -> 11 | R11: =IF(A11='Hora Máx.'!$H$29,(Q11+Q12+Q13+Q15)/(MAX(Q11:Q13,Q15)*4),"") -> #REF!
A12: ='Hora Máx.'!A12 -> 0.3125 | B12: ='Hora Máx.'!B12 -> 0.32291667 | C12: 13 | Q12: =SUM(C12:P12) -> 13 | R12: =IF(A12='Hora Máx.'!$H$29,(Q12+Q13+Q15+Q16)/(MAX(Q12,Q13,Q15,Q16)*4),"") -> #REF!
A13: ='Hora Máx.'!A13 -> 0.32291667 | B13: ='Hora Máx.'!B13 -> 0.33333333 | C13: 9 | Q13: =SUM(C13:P13) -> 9 | R13: =IF(A13='Hora Máx.'!$H$29,(Q13+Q15+Q16+Q17)/(MAX(Q13,Q15:Q17)*4),"") -> #REF!
A15: ='Hora Máx.'!A15 -> 0.33333333 | B15: ='Hora Máx.'!B15 -> 0.34375 | C15: 5 | Q15: =SUM(C15:P15) -> 5 | R15: =IF(A15='Hora Máx.'!$H$29,(Q15+Q16+Q17+Q18)/(MAX(Q15:Q18)*4),"") -> #REF!
A16: ='Hora Máx.'!A16 -> 0.34375 | B16: ='Hora Máx.'!B16 -> 0.35416667 | C16: 3 | Q16: =SUM(C16:P16) -> 3 | R16: =IF(A16='Hora Máx.'!$H$29,(Q16+Q17+Q18+Q20)/(MAX(Q16:Q18,Q20)*4),"") -> #REF!
A17: ='Hora Máx.'!A17 -> 0.35416667 | B17: ='Hora Máx.'!B17 -> 0.36458333 | C17: 17 | Q17: =SUM(C17:P17) -> 17 | R17: =IF(A17='Hora Máx.'!$H$29,(Q17+Q18+Q20+Q21)/(MAX(Q17,Q18,Q20,Q21)*4),"") -> #REF!
A18: ='Hora Máx.'!A18 -> 0.36458333 | B18: ='Hora Máx.'!B18 -> 0.375 | C18: 23 | Q18: =SUM(C18:P18) -> 23 | R18: =IF(A18='Hora Máx.'!$H$29,(Q18+Q20+Q21+Q22)/(MAX(Q18,Q20:Q22)*4),"") -> #REF!
A20: ='Hora Máx.'!A20 -> 0.375 | B20: ='Hora Máx.'!B20 -> 0.38541667 | C20: 13 | Q20: =SUM(C20:P20) -> 13 | R20: =IF(A20='Hora Máx.'!$H$29,(Q20+Q21+Q22+Q23)/(MAX(Q20:Q23)*4),"") -> #REF!
A21: ='Hora Máx.'!A21 -> 0.38541667 | B21: ='Hora Máx.'!B21 -> 0.39583333 | C21: 12 | Q21: =SUM(C21:P21) -> 12
A22: ='Hora Máx.'!A22 -> 0.39583333 | B22: ='Hora Máx.'!B22 -> 0.40625 | C22: 9 | Q22: =SUM(C22:P22) -> 9
A23: ='Hora Máx.'!A23 -> 0.40625 | B23: ='Hora Máx.'!B23 -> 0.41666667 | C23: 5 | Q23: =SUM(C23:P23) -> 5

Sheet 3
C2: MUNICIPIO: | E2: ='Hora Máx.'!E2 -> Monterrey, N.L.
C3: INTERSECCION: | E3: ='Hora Máx.'!E3 -> Int. 03 Av. Fernando García Roel - Ahuehuetes - Los Nogales | K3: FECHA: | L3: ='Hora Máx.'!$H$5
C4: SENTIDO CIRCULACION: | E4: mov. 3 | I4: PERIODO: | J4: ='Hora Máx.'!$E$4 -> 0.29166667 | K4: A: | L4: ='Hora Máx.'!$G$4 -> 0.41666667
C5: ESTADO DEL TIEMPO: | E5: Soleado | I5: PAVIMENTO: | J5: Regular y Seco
A8: LAPSO | C8: AUTOMOVILES | D8: CAMIONETAS | E8: BTR | F8: B | G8: BICICLETAS | H8: C-2 | I8: C-3 | J8: C-4 | K8: C-5 | L8: C-6 | M8: C-7 | N8: C-8 | O8: C-9 | P8: MOTOS | Q8: TOTAL
A9: H:MIN | B9: H:MIN
A10: ='Hora Máx.'!A10 -> 0.29166667 | B10: ='Hora Máx.'!B10 -> 0.30208333 | C10: 217 | F10: 4 | G10: 1 | Q10: =SUM(C10:P10) -> 222 | R10: =IF(A10='Hora Máx.'!$H$29,(Q10+Q11+Q12+Q13)/(MAX(Q10:Q13)*4),"") -> #REF!
A11: ='Hora Máx.'!A11 -> 0.30208333 | B11: ='Hora Máx.'!B11 -> 0.3125 | C11: 147 | F11: 3 | Q11: =SUM(C11:P11) -> 150 | R11: =IF(A11='Hora Máx.'!$H$29,(Q11+Q12+Q13+Q15)/(MAX(Q11:Q13,Q15)*4),"") -> #REF!
A12: ='Hora Máx.'!A12 -> 0.3125 | B12: ='Hora Máx.'!B12 -> 0.32291667 | C12: 111 | F12: 5 | H12: 1 | Q12: =SUM(C12:P12) -> 117 | R12: =IF(A12='Hora Máx.'!$H$29,(Q12+Q13+Q15+Q16)/(MAX(Q12,Q13,Q15,Q16)*4),"") -> #REF!
A13: ='Hora Máx.'!A13 -> 0.32291667 | B13: ='Hora Máx.'!B13 -> 0.33333333 | C13: 203 | F13: 10 | G13: 1 | Q13: =SUM(C13:P13) -> 214 | R13: =IF(A13='Hora Máx.'!$H$29,(Q13+Q15+Q16+Q17)/(MAX(Q13,Q15:Q17)*4),"") -> #REF!
A15: ='Hora Máx.'!A15 -> 0.33333333 | B15: ='Hora Máx.'!B15 -> 0.34375 | C15: 227 | F15: 7 | Q15: =SUM(C15:P15) -> 234 | R15: =IF(A15='Hora Máx.'!$H$29,(Q15+Q16+Q17+Q18)/(MAX(Q15:Q18)*4),"") -> #REF!
A16: ='Hora Máx.'!A16 -> 0.34375 | B16: ='Hora Máx.'!B16 -> 0.35416667 | C16: 315 | F16: 5 | Q16: =SUM(C16:P16) -> 320 | R16: =IF(A16='Hora Máx.'!$H$29,(Q16+Q17+Q18+Q20)/(MAX(Q16:Q18,Q20)*4),"") -> #REF!
A17: ='Hora Máx.'!A17 -> 0.35416667 | B17: ='Hora Máx.'!B17 -> 0.36458333 | C17: 275 | F17: 2 | G17: 3 | Q17: =SUM(C17:P17) -> 280 | R17: =IF(A17='Hora Máx.'!$H$29,(Q17+Q18+Q20+Q21)/(MAX(Q17,Q18,Q20,Q21)*4),"") -> #REF!
A18: ='Hora Máx.'!A18 -> 0.36458333 | B18: ='Hora Máx.'!B18 -> 0.375 | C18: 189 | F18: 4 | H18: 1 | Q18: =SUM(C18:P18) -> 194 | R18: =IF(A18='Hora Máx.'!$H$29,(Q18+Q20+Q21+Q22)/(MAX(Q18,Q20:Q22)*4),"") -> #REF!
A20: ='Hora Máx.'!A20 -> 0.375 | B20: ='Hora Máx.'!B20 -> 0.38541667 | C20: 143 | F20: 5 | Q20: =SUM(C20:P20) -> 148 | R20: =IF(A20='Hora Máx.'!$H$29,(Q20+Q21+Q22+Q23)/(MAX(Q20:Q23)*4),"") -> #REF!
A21: ='Hora Máx.'!A21 -> 0.38541667 | B21: ='Hora Máx.'!B21 -> 0.39583333 | C21: 119 | F21: 3 | Q21: =SUM(C21:P21) -> 122
A22: ='Hora Máx.'!A22 -> 0.39583333 | B22: ='Hora Máx.'!B22 -> 0.40625 | C22: 99 | F22: 4 | G22: 1 | Q22: =SUM(C22:P22) -> 104
A23: ='Hora Máx.'!A23 -> 0.40625 | B23: ='Hora Máx.'!B23 -> 0.41666667 | C23: 110 | F23: 3 | Q23: =SUM(C23:P23) -> 113

Sheet 4
C2: MUNICIPIO: | E2: ='Hora Máx.'!E2 -> Monterrey, N.L.
C3: INTERSECCION: | E3: ='Hora Máx.'!E3 -> Int. 03 Av. Fernando García Roel - Ahuehuetes - Los Nogales | K3: FECHA: | L3: ='Hora Máx.'!$H$5
C4: SENTIDO CIRCULACION: | E4: mov. 4 | I4: PERIODO: | J4: ='Hora Máx.'!$E$4 -> 0.29166667 | K4: A: | L4: ='Hora Máx.'!$G$4 -> 0.41666667
C5: ESTADO DEL TIEMPO: | E5: Soleado | I5: PAVIMENTO: | J5: Regular y Seco
A8: LAPSO | C8: AUTOMOVILES | D8: CAMIONETAS | E8: BTR | F8: B | G8: BICICLETAS | H8: C-2 | I8: C-3 | J8: C-4 | K8: C-5 | L8: C-6 | M8: C-7 | N8: C-8 | O8: C-9 | P8: MOTOS | Q8: TOTAL
A9: H:MIN | B9: H:MIN
A10: ='Hora Máx.'!A10 -> 0.29166667 | B10: ='Hora Máx.'!B10 -> 0.30208333 | C10: 137 | Q10: =SUM(C10:P10) -> 137 | R10: =IF(A10='Hora Máx.'!$H$29,(Q10+Q11+Q12+Q13)/(MAX(Q10:Q13)*4),"") -> #REF!
A11: ='Hora Máx.'!A11 -> 0.30208333 | B11: ='Hora Máx.'!B11 -> 0.3125 | C11: 152 | Q11: =SUM(C11:P11) -> 152 | R11: =IF(A11='Hora Máx.'!$H$29,(Q11+Q12+Q13+Q15)/(MAX(Q11:Q13,Q15)*4),"") -> #REF!
A12: ='Hora Máx.'!A12 -> 0.3125 | B12: ='Hora Máx.'!B12 -> 0.32291667 | C12: 186 | Q12: =SUM(C12:P12) -> 186 | R12: =IF(A12='Hora Máx.'!$H$29,(Q12+Q13+Q15+Q16)/(MAX(Q12,Q13,Q15,Q16)*4),"") -> #REF!
A13: ='Hora Máx.'!A13 -> 0.32291667 | B13: ='Hora Máx.'!B13 -> 0.33333333 | C13: 189 | H13: 1 | Q13: =SUM(C13:P13) -> 190 | R13: =IF(A13='Hora Máx.'!$H$29,(Q13+Q15+Q16+Q17)/(MAX(Q13,Q15:Q17)*4),"") -> #REF!
A15: ='Hora Máx.'!A15 -> 0.33333333 | B15: ='Hora Máx.'!B15 -> 0.34375 | C15: 183 | Q15: =SUM(C15:P15) -> 183 | R15: =IF(A15='Hora Máx.'!$H$29,(Q15+Q16+Q17+Q18)/(MAX(Q15:Q18)*4),"") -> #REF!
A16: ='Hora Máx.'!A16 -> 0.34375 | B16: ='Hora Máx.'!B16 -> 0.35416667 | C16: 164 | Q16: =SUM(C16:P16) -> 164 | R16: =IF(A16='Hora Máx.'!$H$29,(Q16+Q17+Q18+Q20)/(MAX(Q16:Q18,Q20)*4),"") -> #REF!
A17: ='Hora Máx.'!A17 -> 0.35416667 | B17: ='Hora Máx.'!B17 -> 0.36458333 | C17: 148 | H17: 3 | Q17: =SUM(C17:P17) -> 151 | R17: =IF(A17='Hora Máx.'!$H$29,(Q17+Q18+Q20+Q21)/(MAX(Q17,Q18,Q20,Q21)*4),"") -> #REF!
A18: ='Hora Máx.'!A18 -> 0.36458333 | B18: ='Hora Máx.'!B18 -> 0.375 | C18: 132 | Q18: =SUM(C18:P18) -> 132 | R18: =IF(A18='Hora Máx.'!$H$29,(Q18+Q20+Q21+Q22)/(MAX(Q18,Q20:Q22)*4),"") -> #REF!
A20: ='Hora Máx.'!A20 -> 0.375 | B20: ='Hora Máx.'!B20 -> 0.38541667 | C20: 144 | H20: 2 | Q20: =SUM(C20:P20) -> 146 | R20: =IF(A20='Hora Máx.'!$H$29,(Q20+Q21+Q22+Q23)/(MAX(Q20:Q23)*4),"") -> #REF!
A21: ='Hora Máx.'!A21 -> 0.38541667 | B21: ='Hora Máx.'!B21 -> 0.39583333 | C21: 110 | Q21: =SUM(C21:P21) -> 110
A22: ='Hora Máx.'!A22 -> 0.39583333 | B22: ='Hora Máx.'!B22 -> 0.40625 | C22: 104 | Q22: =SUM(C22:P22) -> 104
A23: ='Hora Máx.'!A23 -> 0.40625 | B23: ='Hora Máx.'!B23 -> 0.41666667 | C23: 98 | Q23: =SUM(C23:P23) -> 98

Sheet 5
C2: MUNICIPIO: | E2: ='Hora Máx.'!E2 -> Monterrey, N.L.
C3: INTERSECCION: | E3: ='Hora Máx.'!E3 -> Int. 03 Av. Fernando García Roel - Ahuehuetes - Los Nogales | K3: FECHA: | L3: ='Hora Máx.'!$H$5
C4: SENTIDO CIRCULACION: | E4: mov. 5 | I4: PERIODO: | J4: ='Hora Máx.'!$E$4 -> 0.29166667 | K4: A: | L4: ='Hora Máx.'!$G$4 -> 0.41666667
C5: ESTADO DEL TIEMPO: | E5: Soleado | I5: PAVIMENTO: | J5: Regular y Seco
A8: LAPSO | C8: AUTOMOVILES | D8: CAMIONETAS | E8: BTR | F8: B | G8: BICICLETAS | H8: C-2 | I8: C-3 | J8: C-4 | K8: C-5 | L8: C-6 | M8: C-7 | N8: C-8 | O8: C-9 | P8: MOTOS | Q8: TOTAL
A9: H:MIN | B9: H:MIN
A10: ='Hora Máx.'!A10 -> 0.29166667 | B10: ='Hora Máx.'!B10 -> 0.30208333 | C10: 20 | Q10: =SUM(C10:P10) -> 20 | R10: =IF(A10='Hora Máx.'!$H$29,(Q10+Q11+Q12+Q13)/(MAX(Q10:Q13)*4),"") -> #REF!
A11: ='Hora Máx.'!A11 -> 0.30208333 | B11: ='Hora Máx.'!B11 -> 0.3125 | C11: 27 | G11: 1 | Q11: =SUM(C11:P11) -> 28 | R11: =IF(A11='Hora Máx.'!$H$29,(Q11+Q12+Q13+Q15)/(MAX(Q11:Q13,Q15)*4),"") -> #REF!
A12: ='Hora Máx.'!A12 -> 0.3125 | B12: ='Hora Máx.'!B12 -> 0.32291667 | C12: 29 | Q12: =SUM(C12:P12) -> 29 | R12: =IF(A12='Hora Máx.'!$H$29,(Q12+Q13+Q15+Q16)/(MAX(Q12,Q13,Q15,Q16)*4),"") -> #REF!
A13: ='Hora Máx.'!A13 -> 0.32291667 | B13: ='Hora Máx.'!B13 -> 0.33333333 | C13: 17 | Q13: =SUM(C13:P13) -> 17 | R13: =IF(A13='Hora Máx.'!$H$29,(Q13+Q15+Q16+Q17)/(MAX(Q13,Q15:Q17)*4),"") -> #REF!
A15: ='Hora Máx.'!A15 -> 0.33333333 | B15: ='Hora Máx.'!B15 -> 0.34375 | C15: 13 | G15: 2 | Q15: =SUM(C15:P15) -> 15 | R15: =IF(A15='Hora Máx.'!$H$29,(Q15+Q16+Q17+Q18)/(MAX(Q15:Q18)*4),"") -> #REF!
A16: ='Hora Máx.'!A16 -> 0.34375 | B16: ='Hora Máx.'!B16 -> 0.35416667 | C16: 16 | Q16: =SUM(C16:P16) -> 16 | R16: =IF(A16='Hora Máx.'!$H$29,(Q16+Q17+Q18+Q20)/(MAX(Q16:Q18,Q20)*4),"") -> #REF!
A17: ='Hora Máx.'!A17 -> 0.35416667 | B17: ='Hora Máx.'!B17 -> 0.36458333 | C17: 11 | G17: 1 | H17: 1 | Q17: =SUM(C17:P17) -> 13 | R17: =IF(A17='Hora Máx.'!$H$29,(Q17+Q18+Q20+Q21)/(MAX(Q17,Q18,Q20,Q21)*4),"") -> #REF!
A18: ='Hora Máx.'!A18 -> 0.36458333 | B18: ='Hora Máx.'!B18 -> 0.375 | C18: 10 | Q18: =SUM(C18:P18) -> 10 | R18: =IF(A18='Hora Máx.'!$H$29,(Q18+Q20+Q21+Q22)/(MAX(Q18,Q20:Q22)*4),"") -> #REF!
A20: ='Hora Máx.'!A20 -> 0.375 | B20: ='Hora Máx.'!B20 -> 0.38541667 | C20: 12 | H20: 1 | Q20: =SUM(C20:P20) -> 13 | R20: =IF(A20='Hora Máx.'!$H$29,(Q20+Q21+Q22+Q23)/(MAX(Q20:Q23)*4),"") -> #REF!
A21: ='Hora Máx.'!A21 -> 0.38541667 | B21: ='Hora Máx.'!B21 -> 0.39583333 | C21: 3 | Q21: =SUM(C21:P21) -> 3
A22: ='Hora Máx.'!A22 -> 0.39583333 | B22: ='Hora Máx.'!B22 -> 0.40625 | C22: 5 | Q22: =SUM(C22:P22) -> 5
A23: ='Hora Máx.'!A23 -> 0.40625 | B23: ='Hora Máx.'!B23 -> 0.41666667 | C23: 7 | H23: 1 | Q23: =SUM(C23:P23) -> 8

Sheet 6
C2: MUNICIPIO: | E2: ='Hora Máx.'!E2 -> Monterrey, N.L.
C3: INTERSECCION: | E3: ='Hora Máx.'!E3 -> Int. 03 Av. Fernando García Roel - Ahuehuetes - Los Nogales | K3: FECHA: | L3: ='Hora Máx.'!$H$5
C4: SENTIDO CIRCULACION: | E4: mov. 6 | I4: PERIODO: | J4: ='Hora Máx.'!$E$4 -> 0.29166667 | K4: A: | L4: ='Hora Máx.'!$G$4 -> 0.41666667
C5: ESTADO DEL TIEMPO: | E5: Soleado | I5: PAVIMENTO: | J5: Regular y Seco
A8: LAPSO | C8: AUTOMOVILES | D8: CAMIONETAS | E8: BTR | F8: B | G8: BICICLETAS | H8: C-2 | I8: C-3 | J8: C-4 | K8: C-5 | L8: C-6 | M8: C-7 | N8: C-8 | O8: C-9 | P8: MOTOS | Q8: TOTAL
A9: H:MIN | B9: H:MIN
A10: ='Hora Máx.'!A10 -> 0.29166667 | B10: ='Hora Máx.'!B10 -> 0.30208333 | C10: 12 | Q10: =SUM(C10:P10) -> 12 | R10: =IF(A10='Hora Máx.'!$H$29,(Q10+Q11+Q12+Q13)/(MAX(Q10:Q13)*4),"") -> #REF!
A11: ='Hora Máx.'!A11 -> 0.30208333 | B11: ='Hora Máx.'!B11 -> 0.3125 | C11: 13 | Q11: =SUM(C11:P11) -> 13 | R11: =IF(A11='Hora Máx.'!$H$29,(Q11+Q12+Q13+Q15)/(MAX(Q11:Q13,Q15)*4),"") -> #REF!
A12: ='Hora Máx.'!A12 -> 0.3125 | B12: ='Hora Máx.'!B12 -> 0.32291667 | C12: 26 | Q12: =SUM(C12:P12) -> 26 | R12: =IF(A12='Hora Máx.'!$H$29,(Q12+Q13+Q15+Q16)/(MAX(Q12,Q13,Q15,Q16)*4),"") -> #REF!
A13: ='Hora Máx.'!A13 -> 0.32291667 | B13: ='Hora Máx.'!B13 -> 0.33333333 | C13: 24 | H13: 1 | Q13: =SUM(C13:P13) -> 25 | R13: =IF(A13='Hora Máx.'!$H$29,(Q13+Q15+Q16+Q17)/(MAX(Q13,Q15:Q17)*4),"") -> #REF!
A15: ='Hora Máx.'!A15 -> 0.33333333 | B15: ='Hora Máx.'!B15 -> 0.34375 | C15: 19 | Q15: =SUM(C15:P15) -> 19 | R15: =IF(A15='Hora Máx.'!$H$29,(Q15+Q16+Q17+Q18)/(MAX(Q15:Q18)*4),"") -> #REF!
A16: ='Hora Máx.'!A16 -> 0.34375 | B16: ='Hora Máx.'!B16 -> 0.35416667 | C16: 15 | H16: 1 | Q16: =SUM(C16:P16) -> 16 | R16: =IF(A16='Hora Máx.'!$H$29,(Q16+Q17+Q18+Q20)/(MAX(Q16:Q18,Q20)*4),"") -> #REF!
A17: ='Hora Máx.'!A17 -> 0.35416667 | B17: ='Hora Máx.'!B17 -> 0.36458333 | C17: 1 | Q17: =SUM(C17:P17) -> 1 | R17: =IF(A17='Hora Máx.'!$H$29,(Q17+Q18+Q20+Q21)/(MAX(Q17,Q18,Q20,Q21)*4),"") -> #REF!
A18: ='Hora Máx.'!A18 -> 0.36458333 | B18: ='Hora Máx.'!B18 -> 0.375 | C18: 3 | G18: 1 | Q18: =SUM(C18:P18) -> 4 | R18: =IF(A18='Hora Máx.'!$H$29,(Q18+Q20+Q21+Q22)/(MAX(Q18,Q20:Q22)*4),"") -> #REF!
A20: ='Hora Máx.'!A20 -> 0.375 | B20: ='Hora Máx.'!B20 -> 0.38541667 | C20: 8 | Q20: =SUM(C20:P20) -> 8 | R20: =IF(A20='Hora Máx.'!$H$29,(Q20+Q21+Q22+Q23)/(MAX(Q20:Q23)*4),"") -> #REF!
A21: ='Hora Máx.'!A21 -> 0.38541667 | B21: ='Hora Máx.'!B21 -> 0.39583333 | C21: 5 | Q21: =SUM(C21:P21) -> 5
A22: ='Hora Máx.'!A22 -> 0.39583333 | B22: ='Hora Máx.'!B22 -> 0.40625 | C22: 3 | Q22: =SUM(C22:P22) -> 3
A23: ='Hora Máx.'!A23 -> 0.40625 | B23: ='Hora Máx.'!B23 -> 0.41666667 | C23: 4 | Q23: =SUM(C23:P23) -> 4

Sheet 7
C2: MUNICIPIO: | E2: ='Hora Máx.'!E2 -> Monterrey, N.L.
C3: INTERSECCION: | E3: ='Hora Máx.'!E3 -> Int. 03 Av. Fernando García Roel - Ahuehuetes - Los Nogales | K3: FECHA: | L3: ='Hora Máx.'!$H$5
C4: SENTIDO CIRCULACION: | E4: mov. 7 | I4: PERIODO: | J4: ='Hora Máx.'!$E$4 -> 0.29166667 | K4: A: | L4: ='Hora Máx.'!$G$4 -> 0.41666667
C5: ESTADO DEL TIEMPO: | E5: Soleado | I5: PAVIMENTO: | J5: Regular y Seco
A8: LAPSO | C8: AUTOMOVILES | D8: CAMIONETAS | E8: BTR | F8: B | G8: BICICLETAS | H8: C-2 | I8: C-3 | J8: C-4 | K8: C-5 | L8: C-6 | M8: C-7 | N8: C-8 | O8: C-9 | P8: MOTOS | Q8: TOTAL
A9: H:MIN | B9: H:MIN
A10: ='Hora Máx.'!A10 -> 0.29166667 | B10: ='Hora Máx.'!B10 -> 0.30208333 | C10: 4 | Q10: =SUM(C10:P10) -> 4 | R10: =IF(A10='Hora Máx.'!$H$29,(Q10+Q11+Q12+Q13)/(MAX(Q10:Q13)*4),"") -> #REF!
A11: ='Hora Máx.'!A11 -> 0.30208333 | B11: ='Hora Máx.'!B11 -> 0.3125 | C11: 9 | Q11: =SUM(C11:P11) -> 9 | R11: =IF(A11='Hora Máx.'!$H$29,(Q11+Q12+Q13+Q15)/(MAX(Q11:Q13,Q15)*4),"") -> #REF!
A12: ='Hora Máx.'!A12 -> 0.3125 | B12: ='Hora Máx.'!B12 -> 0.32291667 | C12: 8 | Q12: =SUM(C12:P12) -> 8 | R12: =IF(A12='Hora Máx.'!$H$29,(Q12+Q13+Q15+Q16)/(MAX(Q12,Q13,Q15,Q16)*4),"") -> #REF!
A13: ='Hora Máx.'!A13 -> 0.32291667 | B13: ='Hora Máx.'!B13 -> 0.33333333 | C13: 4 | Q13: =SUM(C13:P13) -> 4 | R13: =IF(A13='Hora Máx.'!$H$29,(Q13+Q15+Q16+Q17)/(MAX(Q13,Q15:Q17)*4),"") -> #REF!
A15: ='Hora Máx.'!A15 -> 0.33333333 | B15: ='Hora Máx.'!B15 -> 0.34375 | C15: 12 | Q15: =SUM(C15:P15) -> 12 | R15: =IF(A15='Hora Máx.'!$H$29,(Q15+Q16+Q17+Q18)/(MAX(Q15:Q18)*4),"") -> #REF!
A16: ='Hora Máx.'!A16 -> 0.34375 | B16: ='Hora Máx.'!B16 -> 0.35416667 | C16: 17 | Q16: =SUM(C16:P16) -> 17 | R16: =IF(A16='Hora Máx.'!$H$29,(Q16+Q17+Q18+Q20)/(MAX(Q16:Q18,Q20)*4),"") -> #REF!
A17: ='Hora Máx.'!A17 -> 0.35416667 | B17: ='Hora Máx.'!B17 -> 0.36458333 | C17: 10 | Q17: =SUM(C17:P17) -> 10 | R17: =IF(A17='Hora Máx.'!$H$29,(Q17+Q18+Q20+Q21)/(MAX(Q17,Q18,Q20,Q21)*4),"") -> #REF!
A18: ='Hora Máx.'!A18 -> 0.36458333 | B18: ='Hora Máx.'!B18 -> 0.375 | C18: 13 | Q18: =SUM(C18:P18) -> 13 | R18: =IF(A18='Hora Máx.'!$H$29,(Q18+Q20+Q21+Q22)/(MAX(Q18,Q20:Q22)*4),"") -> #REF!
A20: ='Hora Máx.'!A20 -> 0.375 | B20: ='Hora Máx.'!B20 -> 0.38541667 | C20: 5 | Q20: =SUM(C20:P20) -> 5 | R20: =IF(A20='Hora Máx.'!$H$29,(Q20+Q21+Q22+Q23)/(MAX(Q20:Q23)*4),"") -> #REF!
A21: ='Hora Máx.'!A21 -> 0.38541667 | B21: ='Hora Máx.'!B21 -> 0.39583333 | C21: 1 | Q21: =SUM(C21:P21) -> 1
A22: ='Hora Máx.'!A22 -> 0.39583333 | B22: ='Hora Máx.'!B22 -> 0.40625 | C22: 2 | Q22: =SUM(C22:P22) -> 2
A23: ='Hora Máx.'!A23 -> 0.40625 | B23: ='Hora Máx.'!B23 -> 0.41666667 | C23: 1 | Q23: =SUM(C23:P23) -> 1

Sheet 8
C2: MUNICIPIO: | E2: ='Hora Máx.'!E2 -> Monterrey, N.L.
C3: INTERSECCION: | E3: ='Hora Máx.'!E3 -> Int. 03 Av. Fernando García Roel - Ahuehuetes - Los Nogales | K3: FECHA: | L3: ='Hora Máx.'!$H$5
C4: SENTIDO CIRCULACION: | E4: mov. 8 | I4: PERIODO: | J4: ='Hora Máx.'!$E$4 -> 0.29166667 | K4: A: | L4: ='Hora Máx.'!$G$4 -> 0.41666667
C5: ESTADO DEL TIEMPO: | E5: Soleado | I5: PAVIMENTO: | J5: Regular y Seco
A8: LAPSO | C8: AUTOMOVILES | D8: CAMIONETAS | E8: BTR | F8: B | G8: BICICLETAS | H8: C-2 | I8: C-3 | J8: C-4 | K8: C-5 | L8: C-6 | M8: C-7 | N8: C-8 | O8: C-9 | P8: MOTOS | Q8: TOTAL
A9: H:MIN | B9: H:MIN
A10: ='Hora Máx.'!A10 -> 0.29166667 | B10: ='Hora Máx.'!B10 -> 0.30208333 | C10: 5 | Q10: =SUM(C10:P10) -> 5 | R10: =IF(A10='Hora Máx.'!$H$29,(Q10+Q11+Q12+Q13)/(MAX(Q10:Q13)*4),"") -> #REF!
A11: ='Hora Máx.'!A11 -> 0.30208333 | B11: ='Hora Máx.'!B11 -> 0.3125 | C11: 13 | Q11: =SUM(C11:P11) -> 13 | R11: =IF(A11='Hora Máx.'!$H$29,(Q11+Q12+Q13+Q15)/(MAX(Q11:Q13,Q15)*4),"") -> #REF!
A12: ='Hora Máx.'!A12 -> 0.3125 | B12: ='Hora Máx.'!B12 -> 0.32291667 | C12: 8 | Q12: =SUM(C12:P12) -> 8 | R12: =IF(A12='Hora Máx.'!$H$29,(Q12+Q13+Q15+Q16)/(MAX(Q12,Q13,Q15,Q16)*4),"") -> #REF!
A13: ='Hora Máx.'!A13 -> 0.32291667 | B13: ='Hora Máx.'!B13 -> 0.33333333 | C13: 11 | Q13: =SUM(C13:P13) -> 11 | R13: =IF(A13='Hora Máx.'!$H$29,(Q13+Q15+Q16+Q17)/(MAX(Q13,Q15:Q17)*4),"") -> #REF!
A15: ='Hora Máx.'!A15 -> 0.33333333 | B15: ='Hora Máx.'!B15 -> 0.34375 | C15: 7 | Q15: =SUM(C15:P15) -> 7 | R15: =IF(A15='Hora Máx.'!$H$29,(Q15+Q16+Q17+Q18)/(MAX(Q15:Q18)*4),"") -> #REF!
A16: ='Hora Máx.'!A16 -> 0.34375 | B16: ='Hora Máx.'!B16 -> 0.35416667 | C16: 12 | Q16: =SUM(C16:P16) -> 12 | R16: =IF(A16='Hora Máx.'!$H$29,(Q16+Q17+Q18+Q20)/(MAX(Q16:Q18,Q20)*4),"") -> #REF!
A17: ='Hora Máx.'!A17 -> 0.35416667 | B17: ='Hora Máx.'!B17 -> 0.36458333 | C17: 4 | Q17: =SUM(C17:P17) -> 4 | R17: =IF(A17='Hora Máx.'!$H$29,(Q17+Q18+Q20+Q21)/(MAX(Q17,Q18,Q20,Q21)*4),"") -> #REF!
A18: ='Hora Máx.'!A18 -> 0.36458333 | B18: ='Hora Máx.'!B18 -> 0.375 | C18: 2 | Q18: =SUM(C18:P18) -> 2 | R18: =IF(A18='Hora Máx.'!$H$29,(Q18+Q20+Q21+Q22)/(MAX(Q18,Q20:Q22)*4),"") -> #REF!
A20: ='Hora Máx.'!A20 -> 0.375 | B20: ='Hora Máx.'!B20 -> 0.38541667 | C20: 11 | Q20: =SUM(C20:P20) -> 11 | R20: =IF(A20='Hora Máx.'!$H$29,(Q20+Q21+Q22+Q23)/(MAX(Q20:Q23)*4),"") -> #REF!
A21: ='Hora Máx.'!A21 -> 0.38541667 | B21: ='Hora Máx.'!B21 -> 0.39583333 | C21: 5 | Q21: =SUM(C21:P21) -> 5
A22: ='Hora Máx.'!A22 -> 0.39583333 | B22: ='Hora Máx.'!B22 -> 0.40625 | C22: 3 | Q22: =SUM(C22:P22) -> 3
A23: ='Hora Máx.'!A23 -> 0.40625 | B23: ='Hora Máx.'!B23 -> 0.41666667 | C23: 5 | Q23: =SUM(C23:P23) -> 5

Sheet 9
C2: MUNICIPIO: | E2: ='Hora Máx.'!E2 -> Monterrey, N.L.
C3: INTERSECCION: | E3: ='Hora Máx.'!E3 -> Int. 03 Av. Fernando García Roel - Ahuehuetes - Los Nogales | K3: FECHA: | L3: ='Hora Máx.'!$H$5
C4: SENTIDO CIRCULACION: | E4: mov. 9 | I4: PERIODO: | J4: ='Hora Máx.'!$E$4 -> 0.29166667 | K4: A: | L4: ='Hora Máx.'!$G$4 -> 0.41666667
C5: ESTADO DEL TIEMPO: | E5: Soleado | I5: PAVIMENTO: | J5: Regular y Seco
A8: LAPSO | C8: AUTOMOVILES | D8: CAMIONETAS | E8: BTR | F8: B | G8: BICICLETAS | H8: C-2 | I8: C-3 | J8: C-4 | K8: C-5 | L8: C-6 | M8: C-7 | N8: C-8 | O8: C-9 | P8: MOTOS | Q8: TOTAL
A9: H:MIN | B9: H:MIN
A10: ='Hora Máx.'!A10 -> 0.29166667 | B10: ='Hora Máx.'!B10 -> 0.30208333 | C10: 5 | Q10: =SUM(C10:P10) -> 5 | R10: =IF(A10='Hora Máx.'!$H$29,(Q10+Q11+Q12+Q13)/(MAX(Q10:Q13)*4),"") -> #REF!
A11: ='Hora Máx.'!A11 -> 0.30208333 | B11: ='Hora Máx.'!B11 -> 0.3125 | C11: 3 | Q11: =SUM(C11:P11) -> 3 | R11: =IF(A11='Hora Máx.'!$H$29,(Q11+Q12+Q13+Q15)/(MAX(Q11:Q13,Q15)*4),"") -> #REF!
A12: ='Hora Máx.'!A12 -> 0.3125 | B12: ='Hora Máx.'!B12 -> 0.32291667 | C12: 3 | Q12: =SUM(C12:P12) -> 3 | R12: =IF(A12='Hora Máx.'!$H$29,(Q12+Q13+Q15+Q16)/(MAX(Q12,Q13,Q15,Q16)*4),"") -> #REF!
A13: ='Hora Máx.'!A13 -> 0.32291667 | B13: ='Hora Máx.'!B13 -> 0.33333333 | Q13: =SUM(C13:P13) -> 0 | R13: =IF(A13='Hora Máx.'!$H$29,(Q13+Q15+Q16+Q17)/(MAX(Q13,Q15:Q17)*4),"") -> #REF!
A15: ='Hora Máx.'!A15 -> 0.33333333 | B15: ='Hora Máx.'!B15 -> 0.34375 | C15: 1 | Q15: =SUM(C15:P15) -> 1 | R15: =IF(A15='Hora Máx.'!$H$29,(Q15+Q16+Q17+Q18)/(MAX(Q15:Q18)*4),"") -> #REF!
A16: ='Hora Máx.'!A16 -> 0.34375 | B16: ='Hora Máx.'!B16 -> 0.35416667 | C16: 2 | Q16: =SUM(C16:P16) -> 2 | R16: =IF(A16='Hora Máx.'!$H$29,(Q16+Q17+Q18+Q20)/(MAX(Q16:Q18,Q20)*4),"") -> #REF!
A17: ='Hora Máx.'!A17 -> 0.35416667 | B17: ='Hora Máx.'!B17 -> 0.36458333 | C17: 4 | Q17: =SUM(C17:P17) -> 4 | R17: =IF(A17='Hora Máx.'!$H$29,(Q17+Q18+Q20+Q21)/(MAX(Q17,Q18,Q20,Q21)*4),"") -> #REF!
A18: ='Hora Máx.'!A18 -> 0.36458333 | B18: ='Hora Máx.'!B18 -> 0.375 | C18: 1 | Q18: =SUM(C18:P18) -> 1 | R18: =IF(A18='Hora Máx.'!$H$29,(Q18+Q20+Q21+Q22)/(MAX(Q18,Q20:Q22)*4),"") -> #REF!
A20: ='Hora Máx.'!A20 -> 0.375 | B20: ='Hora Máx.'!B20 -> 0.38541667 | C20: 1 | Q20: =SUM(C20:P20) -> 1 | R20: =IF(A20='Hora Máx.'!$H$29,(Q20+Q21+Q22+Q23)/(MAX(Q20:Q23)*4),"") -> #REF!
A21: ='Hora Máx.'!A21 -> 0.38541667 | B21: ='Hora Máx.'!B21 -> 0.39583333 | Q21: =SUM(C21:P21) -> 0
A22: ='Hora Máx.'!A22 -> 0.39583333 | B22: ='Hora Máx.'!B22 -> 0.40625 | C22: 2 | Q22: =SUM(C22:P22) -> 2
A23: ='Hora Máx.'!A23 -> 0.40625 | B23: ='Hora Máx.'!B23 -> 0.41666667 | Q23: =SUM(C23:P23) -> 0

Sheet 10
C2: MUNICIPIO: | E2: ='Hora Máx.'!E2 -> Monterrey, N.L.
C3: INTERSECCION: | E3: ='Hora Máx.'!E3 -> Int. 03 Av. Fernando García Roel - Ahuehuetes - Los Nogales | K3: FECHA: | L3: ='Hora Máx.'!$H$5
C4: SENTIDO CIRCULACION: | E4: mov. 10 | I4: PERIODO: | J4: ='Hora Máx.'!$E$4 -> 0.29166667 | K4: A: | L4: ='Hora Máx.'!$G$4 -> 0.41666667
C5: ESTADO DEL TIEMPO: | E5: Soleado | I5: PAVIMENTO: | J5: Regular y Seco
A8: LAPSO | C8: AUTOMOVILES | D8: CAMIONETAS | E8: BTR | F8: B | G8: BICICLETAS | H8: C-2 | I8: C-3 | J8: C-4 | K8: C-5 | L8: C-6 | M8: C-7 | N8: C-8 | O8: C-9 | P8: MOTOS | Q8: TOTAL
A9: H:MIN | B9: H:MIN
A10: ='Hora Máx.'!A10 -> 0.29166667 | B10: ='Hora Máx.'!B10 -> 0.30208333 | C10: 7 | Q10: =SUM(C10:P10) -> 7 | R10: =IF(A10='Hora Máx.'!$H$29,(Q10+Q11+Q12+Q13)/(MAX(Q10:Q13)*4),"") -> #REF!
A11: ='Hora Máx.'!A11 -> 0.30208333 | B11: ='Hora Máx.'!B11 -> 0.3125 | C11: 4 | Q11: =SUM(C11:P11) -> 4 | R11: =IF(A11='Hora Máx.'!$H$29,(Q11+Q12+Q13+Q15)/(MAX(Q11:Q13,Q15)*4),"") -> #REF!
A12: ='Hora Máx.'!A12 -> 0.3125 | B12: ='Hora Máx.'!B12 -> 0.32291667 | C12: 9 | Q12: =SUM(C12:P12) -> 9 | R12: =IF(A12='Hora Máx.'!$H$29,(Q12+Q13+Q15+Q16)/(MAX(Q12,Q13,Q15,Q16)*4),"") -> #REF!
A13: ='Hora Máx.'!A13 -> 0.32291667 | B13: ='Hora Máx.'!B13 -> 0.33333333 | C13: 2 | Q13: =SUM(C13:P13) -> 2 | R13: =IF(A13='Hora Máx.'!$H$29,(Q13+Q15+Q16+Q17)/(MAX(Q13,Q15:Q17)*4),"") -> #REF!
A15: ='Hora Máx.'!A15 -> 0.33333333 | B15: ='Hora Máx.'!B15 -> 0.34375 | C15: 3 | Q15: =SUM(C15:P15) -> 3 | R15: =IF(A15='Hora Máx.'!$H$29,(Q15+Q16+Q17+Q18)/(MAX(Q15:Q18)*4),"") -> #REF!
A16: ='Hora Máx.'!A16 -> 0.34375 | B16: ='Hora Máx.'!B16 -> 0.35416667 | C16: 2 | Q16: =SUM(C16:P16) -> 2 | R16: =IF(A16='Hora Máx.'!$H$29,(Q16+Q17+Q18+Q20)/(MAX(Q16:Q18,Q20)*4),"") -> #REF!
A17: ='Hora Máx.'!A17 -> 0.35416667 | B17: ='Hora Máx.'!B17 -> 0.36458333 | C17: 1 | Q17: =SUM(C17:P17) -> 1 | R17: =IF(A17='Hora Máx.'!$H$29,(Q17+Q18+Q20+Q21)/(MAX(Q17,Q18,Q20,Q21)*4),"") -> #REF!
A18: ='Hora Máx.'!A18 -> 0.36458333 | B18: ='Hora Máx.'!B18 -> 0.375 | C18: 3 | Q18: =SUM(C18:P18) -> 3 | R18: =IF(A18='Hora Máx.'!$H$29,(Q18+Q20+Q21+Q22)/(MAX(Q18,Q20:Q22)*4),"") -> #REF!
A20: ='Hora Máx.'!A20 -> 0.375 | B20: ='Hora Máx.'!B20 -> 0.38541667 | C20: 1 | Q20: =SUM(C20:P20) -> 1 | R20: =IF(A20='Hora Máx.'!$H$29,(Q20+Q21+Q22+Q23)/(MAX(Q20:Q23)*4),"") -> #REF!
A21: ='Hora Máx.'!A21 -> 0.38541667 | B21: ='Hora Máx.'!B21 -> 0.39583333 | C21: 1 | Q21: =SUM(C21:P21) -> 1
A22: ='Hora Máx.'!A22 -> 0.39583333 | B22: ='Hora Máx.'!B22 -> 0.40625 | C22: 2 | Q22: =SUM(C22:P22) -> 2
A23: ='Hora Máx.'!A23 -> 0.40625 | B23: ='Hora Máx.'!B23 -> 0.41666667 | C23: 1 | Q23: =SUM(C23:P23) -> 1

Sheet 11
C2: MUNICIPIO: | E2: ='Hora Máx.'!E2 -> Monterrey, N.L.
C3: INTERSECCION: | E3: ='Hora Máx.'!E3 -> Int. 03 Av. Fernando García Roel - Ahuehuetes - Los Nogales | K3: FECHA: | L3: ='Hora Máx.'!$H$5
C4: SENTIDO CIRCULACION: | E4: mov. 11 | I4: PERIODO: | J4: ='Hora Máx.'!$E$4 -> 0.29166667 | K4: A: | L4: ='Hora Máx.'!$G$4 -> 0.41666667
C5: ESTADO DEL TIEMPO: | E5: Soleado | I5: PAVIMENTO: | J5: Regular y Seco
A8: LAPSO | C8: AUTOMOVILES | D8: CAMIONETAS | E8: BTR | F8: B | G8: BICICLETAS | H8: C-2 | I8: C-3 | J8: C-4 | K8: C-5 | L8: C-6 | M8: C-7 | N8: C-8 | O8: C-9 | P8: MOTOS | Q8: TOTAL
A9: H:MIN | B9: H:MIN
A10: ='Hora Máx.'!A10 -> 0.29166667 | B10: ='Hora Máx.'!B10 -> 0.30208333 | C10: 5 | Q10: =SUM(C10:P10) -> 5 | R10: =IF(A10='Hora Máx.'!$H$29,(Q10+Q11+Q12+Q13)/(MAX(Q10:Q13)*4),"") -> #REF!
A11: ='Hora Máx.'!A11 -> 0.30208333 | B11: ='Hora Máx.'!B11 -> 0.3125 | C11: 12 | Q11: =SUM(C11:P11) -> 12 | R11: =IF(A11='Hora Máx.'!$H$29,(Q11+Q12+Q13+Q15)/(MAX(Q11:Q13,Q15)*4),"") -> #REF!
A12: ='Hora Máx.'!A12 -> 0.3125 | B12: ='Hora Máx.'!B12 -> 0.32291667 | C12: 16 | Q12: =SUM(C12:P12) -> 16 | R12: =IF(A12='Hora Máx.'!$H$29,(Q12+Q13+Q15+Q16)/(MAX(Q12,Q13,Q15,Q16)*4),"") -> #REF!
A13: ='Hora Máx.'!A13 -> 0.32291667 | B13: ='Hora Máx.'!B13 -> 0.33333333 | C13: 13 | Q13: =SUM(C13:P13) -> 13 | R13: =IF(A13='Hora Máx.'!$H$29,(Q13+Q15+Q16+Q17)/(MAX(Q13,Q15:Q17)*4),"") -> #REF!
A15: ='Hora Máx.'!A15 -> 0.33333333 | B15: ='Hora Máx.'!B15 -> 0.34375 | C15: 9 | Q15: =SUM(C15:P15) -> 9 | R15: =IF(A15='Hora Máx.'!$H$29,(Q15+Q16+Q17+Q18)/(MAX(Q15:Q18)*4),"") -> #REF!
A16: ='Hora Máx.'!A16 -> 0.34375 | B16: ='Hora Máx.'!B16 -> 0.35416667 | C16: 10 | Q16: =SUM(C16:P16) -> 10 | R16: =IF(A16='Hora Máx.'!$H$29,(Q16+Q17+Q18+Q20)/(MAX(Q16:Q18,Q20)*4),"") -> #REF!
A17: ='Hora Máx.'!A17 -> 0.35416667 | B17: ='Hora Máx.'!B17 -> 0.36458333 | C17: 11 | Q17: =SUM(C17:P17) -> 11 | R17: =IF(A17='Hora Máx.'!$H$29,(Q17+Q18+Q20+Q21)/(MAX(Q17,Q18,Q20,Q21)*4),"") -> #REF!
A18: ='Hora Máx.'!A18 -> 0.36458333 | B18: ='Hora Máx.'!B18 -> 0.375 | C18: 7 | Q18: =SUM(C18:P18) -> 7 | R18: =IF(A18='Hora Máx.'!$H$29,(Q18+Q20+Q21+Q22)/(MAX(Q18,Q20:Q22)*4),"") -> #REF!
A20: ='Hora Máx.'!A20 -> 0.375 | B20: ='Hora Máx.'!B20 -> 0.38541667 | C20: 4 | Q20: =SUM(C20:P20) -> 4 | R20: =IF(A20='Hora Máx.'!$H$29,(Q20+Q21+Q22+Q23)/(MAX(Q20:Q23)*4),"") -> #REF!
A21: ='Hora Máx.'!A21 -> 0.38541667 | B21: ='Hora Máx.'!B21 -> 0.39583333 | C21: 3 | Q21: =SUM(C21:P21) -> 3
A22: ='Hora Máx.'!A22 -> 0.39583333 | B22: ='Hora Máx.'!B22 -> 0.40625 | C22: 3 | Q22: =SUM(C22:P22) -> 3
A23: ='Hora Máx.'!A23 -> 0.40625 | B23: ='Hora Máx.'!B23 -> 0.41666667 | C23: 1 | Q23: =SUM(C23:P23) -> 1

Sheet 12
C2: MUNICIPIO: | E2: ='Hora Máx.'!E2 -> Monterrey, N.L.
C3: INTERSECCION: | E3: ='Hora Máx.'!E3 -> Int. 03 Av. Fernando García Roel - Ahuehuetes - Los Nogales | K3: FECHA: | L3: ='Hora Máx.'!$H$5
C4: SENTIDO CIRCULACION: | E4: mov. 12 | I4: PERIODO: | J4: ='Hora Máx.'!$E$4 -> 0.29166667 | K4: A: | L4: ='Hora Máx.'!$G$4 -> 0.41666667
C5: ESTADO DEL TIEMPO: | E5: Soleado | I5: PAVIMENTO: | J5: Regular y Seco
A8: LAPSO | C8: AUTOMOVILES | D8: CAMIONETAS | E8: BTR | F8: B | G8: BICICLETAS | H8: C-2 | I8: C-3 | J8: C-4 | K8: C-5 | L8: C-6 | M8: C-7 | N8: C-8 | O8: C-9 | P8: MOTOS | Q8: TOTAL
A9: H:MIN | B9: H:MIN
A10: ='Hora Máx.'!A10 -> 0.29166667 | B10: ='Hora Máx.'!B10 -> 0.30208333 | C10: 8 | Q10: =SUM(C10:P10) -> 8 | R10: =IF(A10='Hora Máx.'!$H$29,(Q10+Q11+Q12+Q13)/(MAX(Q10:Q13)*4),"") -> #REF!
A11: ='Hora Máx.'!A11 -> 0.30208333 | B11: ='Hora Máx.'!B11 -> 0.3125 | C11: 9 | Q11: =SUM(C11:P11) -> 9 | R11: =IF(A11='Hora Máx.'!$H$29,(Q11+Q12+Q13+Q15)/(MAX(Q11:Q13,Q15)*4),"") -> #REF!
A12: ='Hora Máx.'!A12 -> 0.3125 | B12: ='Hora Máx.'!B12 -> 0.32291667 | C12: 13 | Q12: =SUM(C12:P12) -> 13 | R12: =IF(A12='Hora Máx.'!$H$29,(Q12+Q13+Q15+Q16)/(MAX(Q12,Q13,Q15,Q16)*4),"") -> #REF!
A13: ='Hora Máx.'!A13 -> 0.32291667 | B13: ='Hora Máx.'!B13 -> 0.33333333 | C13: 7 | Q13: =SUM(C13:P13) -> 7 | R13: =IF(A13='Hora Máx.'!$H$29,(Q13+Q15+Q16+Q17)/(MAX(Q13,Q15:Q17)*4),"") -> #REF!
A15: ='Hora Máx.'!A15 -> 0.33333333 | B15: ='Hora Máx.'!B15 -> 0.34375 | C15: 9 | Q15: =SUM(C15:P15) -> 9 | R15: =IF(A15='Hora Máx.'!$H$29,(Q15+Q16+Q17+Q18)/(MAX(Q15:Q18)*4),"") -> #REF!
A16: ='Hora Máx.'!A16 -> 0.34375 | B16: ='Hora Máx.'!B16 -> 0.35416667 | C16: 5 | Q16: =SUM(C16:P16) -> 5 | R16: =IF(A16='Hora Máx.'!$H$29,(Q16+Q17+Q18+Q20)/(MAX(Q16:Q18,Q20)*4),"") -> #REF!
A17: ='Hora Máx.'!A17 -> 0.35416667 | B17: ='Hora Máx.'!B17 -> 0.36458333 | C17: 10 | Q17: =SUM(C17:P17) -> 10 | R17: =IF(A17='Hora Máx.'!$H$29,(Q17+Q18+Q20+Q21)/(MAX(Q17,Q18,Q20,Q21)*4),"") -> #REF!
A18: ='Hora Máx.'!A18 -> 0.36458333 | B18: ='Hora Máx.'!B18 -> 0.375 | C18: 7 | Q18: =SUM(C18:P18) -> 7 | R18: =IF(A18='Hora Máx.'!$H$29,(Q18+Q20+Q21+Q22)/(MAX(Q18,Q20:Q22)*4),"") -> #REF!
A20: ='Hora Máx.'!A20 -> 0.375 | B20: ='Hora Máx.'!B20 -> 0.38541667 | C20: 5 | Q20: =SUM(C20:P20) -> 5 | R20: =IF(A20='Hora Máx.'!$H$29,(Q20+Q21+Q22+Q23)/(MAX(Q20:Q23)*4),"") -> #REF!
A21: ='Hora Máx.'!A21 -> 0.38541667 | B21: ='Hora Máx.'!B21 -> 0.39583333 | C21: 4 | Q21: =SUM(C21:P21) -> 4
A22: ='Hora Máx.'!A22 -> 0.39583333 | B22: ='Hora Máx.'!B22 -> 0.40625 | C22: 4 | Q22: =SUM(C22:P22) -> 4
A23: ='Hora Máx.'!A23 -> 0.40625 | B23: ='Hora Máx.'!B23 -> 0.41666667 | C23: 2 | Q23: =SUM(C23:P23) -> 2

Sheet Vol. Dir.
C2: MUNICIPIO: | E2: ='Hora Máx.'!$E$2 -> Monterrey, N.L.
C3: INTERSECCION: | E3: ='Hora Máx.'!$E$3 -> Int. 03 Av. Fernando García Roel - Ahuehuetes - Los Nogales
C4: PERIODO: | E4: ='Hora Máx.'!$E$4 -> 0.29166667 | G4: A: | H4: ='Hora Máx.'!$G$4 -> 0.41666667
C5: HORA MAXIMA: | E5: ='Hora Máx.'!H29 -> #REF! | G5: A: | H5: ='Hora Máx.'!I29 -> #REF!
C6: FECHA: | E6: ='Hora Máx.'!$H$5
A8: MOVIMIENTO | B8: VOLUMEN | N8: TOTAL | P8: TOTAL | Q8: FHMD | R8: %HV
A9: Nº | B9: A | C9: % | D9: BTR | E9: % | F9: B | G9: % | H9: BICI | I9: % | J9: C | K9: % | L9: M | M9: %
A10: 1 | B10: =CHOOSE($O$10,SUM('1'!$C$10:$C$13,'1'!$D$10:$D$13),SUM('1'!$C$11:$C$15,'1'!$D$11:$D$15),SUM('1'!$C$12:$C$16,'1'!$D$12:$D$16),SUM('1'!$C$13:$C$17,'1'!$D$13:$D$17),SUM('1'!$C$15:$C$18,'1'!$D$15:$D$18),SUM('1'!$C$16:$C$20,'1'!$D$16:$D$20),SUM('1'!$C$17:$C$21,'1'!$D$17:$D$21),SUM('1'!$C$18:$C$22,'1'!$D$18:$D$22),SUM('1'!$C$20:$C$23,'1'!$D$20:$D$23)) -> #REF! | C10: =IF(N10="","",B10/CHOOSE($O$10,SUM('1'!$Q$10:$Q$13),SUM('1'!$Q$11:$Q$15),SUM('1'!$Q$12:$Q$16),SUM('1'!$Q$13:$Q$17),SUM('1'!$Q$15:$Q$18),SUM('1'!$Q$16:$Q$20),SUM('1'!$Q$17:$Q$21),SUM('1'!$Q$18:$Q$22),SUM('1'!$Q$20:$Q$23))) -> #REF! | D10: =CHOOSE($O$10,SUM('1'!$E$10:$E$13),SUM('1'!$E$11:$E$15),SUM('1'!$E$12:$E$16),SUM('1'!$E$13:$E$17),SUM('1'!$E$15:$E$18),SUM('1'!$E$16:$E$20),SUM('1'!$E$17:$E$21),SUM('1'!$E$18:$E$22),SUM('1'!$E$20:$E$23)) -> #REF! | E10: =IF(N10="","",D10/CHOOSE($O$10,SUM('1'!$Q$10:$Q$13),SUM('1'!$Q$11:$Q$15),SUM('1'!$Q$12:$Q$16),SUM('1'!$Q$13:$Q$17),SUM('1'!$Q$15:$Q$18),SUM('1'!$Q$16:$Q$20),SUM('1'!$Q$17:$Q$21),SUM('1'!$Q$18:$Q$22),SUM('1'!$Q$20:$Q$23))) -> #REF! | F10: =CHOOSE($O$10,SUM('1'!$F$10:$F$13),SUM('1'!$F$11:$F$15),SUM('1'!$F$12:$F$16),SUM('1'!$F$13:$F$17),SUM('1'!$F$15:$F$18),SUM('1'!$F$16:$F$20),SUM('1'!$F$17:$F$21),SUM('1'!$F$18:$F$22),SUM('1'!$F$20:$F$23)) -> #REF! | G10: =IF(N10="","",F10/CHOOSE($O$10,SUM('1'!$Q$10:$Q$13),SUM('1'!$Q$11:$Q$15),SUM('1'!$Q$12:$Q$16),SUM('1'!$Q$13:$Q$17),SUM('1'!$Q$15:$Q$18),SUM('1'!$Q$16:$Q$20),SUM('1'!$Q$17:$Q$21),SUM('1'!$Q$18:$Q$22),SUM('1'!$Q$20:$Q$23))) -> #REF! | H10: =CHOOSE($O$10,SUM('1'!$G$10:$G$13),SUM('1'!$G$11:$G$15),SUM('1'!$G$12:$G$16),SUM('1'!$G$13:$G$17),SUM('1'!$G$15:$G$18),SUM('1'!$G$16:$G$20),SUM('1'!$G$17:$G$21),SUM('1'!$G$18:$G$22),SUM('1'!$G$20:$G$23)) -> #REF! | I10: =IF(N10="","",H10/CHOOSE($O$10,SUM('1'!$Q$10:$Q$13),SUM('1'!$Q$11:$Q$15),SUM('1'!$Q$12:$Q$16),SUM('1'!$Q$13:$Q$17),SUM('1'!$Q$15:$Q$18),SUM('1'!$Q$16:$Q$20),SUM('1'!$Q$17:$Q$21),SUM('1'!$Q$18:$Q$22),SUM('1'!$Q$20:$Q$23))) -> #REF! | J10: =CHOOSE($O$10,SUM('1'!$H$10:$O$13),SUM('1'!$H$11:$O$15),SUM('1'!$H$12:$O$16),SUM('1'!$H$13:$O$17),SUM('1'!$H$15:$O$18),SUM('1'!$H$16:$O$20),SUM('1'!$H$17:$O$21),SUM('1'!$H$18:$O$22),SUM('1'!$H$20:$O$23)) -> #REF! | K10: =IF(N10="","",J10/CHOOSE($O$10,SUM('1'!$Q$10:$Q$13),SUM('1'!$Q$11:$Q$15),SUM('1'!$Q$12:$Q$16),SUM('1'!$Q$13:$Q$17),SUM('1'!$Q$15:$Q$18),SUM('1'!$Q$16:$Q$20),SUM('1'!$Q$17:$Q$21),SUM('1'!$Q$18:$Q$22),SUM('1'!$Q$20:$Q$23))) -> #REF! | L10: =CHOOSE($O$10,SUM('1'!$P$10:$P$13),SUM('1'!$P$11:$P$15),SUM('1'!$P$12:$P$16),SUM('1'!$P$13:$P$17),SUM('1'!$P$15:$P$18),SUM('1'!$P$16:$P$20),SUM('1'!$P$17:$P$21),SUM('1'!$P$18:$P$22),SUM('1'!$P$20:$P$23)) -> #REF! | M10: =IF(N10="","",L10/CHOOSE($O$10,SUM('1'!$Q$10:$Q$13),SUM('1'!$Q$11:$Q$15),SUM('1'!$Q$12:$Q$16),SUM('1'!$Q$13:$Q$17),SUM('1'!$Q$15:$Q$18),SUM('1'!$Q$16:$Q$20),SUM('1'!$Q$17:$Q$21),SUM('1'!$Q$18:$Q$22),SUM('1'!$Q$20:$Q$23))) -> #REF! | N10: =IF(B10+D10+F10+H10+J10+L10=0,"",B10+D10+F10+H10+J10+L10) -> #REF! | O10: =IF('Hora Máx.'!H29='Hora Máx.'!A10,1,IF('Hora Máx.'!H29='Hora Máx.'!A11,2,IF('Hora Máx.'!H29='Hora Máx.'!A12,3,IF('Hora Máx.'!H29='Hora Máx.'!A13,4,IF('Hora Máx.'!H29='Hora Máx.'!A15,5,IF('Hora Máx.'!H29='Hora Máx.'!A16,6,IF('Hora Máx.'!H29='Hora Máx.'!A17,7,IF('Hora Máx.'!H29='Hora Máx.'!A18,8,9)))))))) -> #REF! | P10: =N10 -> #REF! | Q10: =IF(N10="","",MAX('1'!$R$10:$R$23)) -> #REF! | R10: =IF(SUM(D10,F10,J10)=0,"",SUM(D10,F10,J10)/N10) -> #REF!
A11: 2 | B11: =CHOOSE($O$10,SUM('2'!$C$10:$C$13,'2'!$D$10:$D$13),SUM('2'!$C$11:$C$15,'2'!$D$11:$D$15),SUM('2'!$C$12:$C$16,'2'!$D$12:$D$16),SUM('2'!$C$13:$C$17,'2'!$D$13:$D$17),SUM('2'!$C$15:$C$18,'2'!$D$15:$D$18),SUM('2'!$C$16:$C$20,'2'!$D$16:$D$20),SUM('2'!$C$17:$C$21,'2'!$D$17:$D$21),SUM('2'!$C$18:$C$22,'2'!$D$18:$D$22),SUM('2'!$C$20:$C$23,'2'!$D$20:$D$23)) -> #REF! | C11: =IF(N11="","",B11/CHOOSE($O$10,SUM('2'!$Q$10:$Q$13),SUM('2'!$Q$11:$Q$15),SUM('2'!$Q$12:$Q$16),SUM('2'!$Q$13:$Q$17),SUM('2'!$Q$15:$Q$18),SUM('2'!$Q$16:$Q$20),SUM('2'!$Q$17:$Q$21),SUM('2'!$Q$18:$Q$22),SUM('2'!$Q$20:$Q$23))) -> #REF! | D11: =CHOOSE($O$10,SUM('2'!$E$10:$E$13),SUM('2'!$E$11:$E$15),SUM('2'!$E$12:$E$16),SUM('2'!$E$13:$E$17),SUM('2'!$E$15:$E$18),SUM('2'!$E$16:$E$20),SUM('2'!$E$17:$E$21),SUM('2'!$E$18:$E$22),SUM('2'!$E$20:$E$23)) -> #REF! | E11: =IF(N11="","",D11/CHOOSE($O$10,SUM('2'!$Q$10:$Q$13),SUM('2'!$Q$11:$Q$15),SUM('2'!$Q$12:$Q$16),SUM('2'!$Q$13:$Q$17),SUM('2'!$Q$15:$Q$18),SUM('2'!$Q$16:$Q$20),SUM('2'!$Q$17:$Q$21),SUM('2'!$Q$18:$Q$22),SUM('2'!$Q$20:$Q$23))) -> #REF! | F11: =CHOOSE($O$10,SUM('2'!$F$10:$F$13),SUM('2'!$F$11:$F$15),SUM('2'!$F$12:$F$16),SUM('2'!$F$13:$F$17),SUM('2'!$F$15:$F$18),SUM('2'!$F$16:$F$20),SUM('2'!$F$17:$F$21),SUM('2'!$F$18:$F$22),SUM('2'!$F$20:$F$23)) -> #REF! | G11: =IF(N11="","",F11/CHOOSE($O$10,SUM('2'!$Q$10:$Q$13),SUM('2'!$Q$11:$Q$15),SUM('2'!$Q$12:$Q$16),SUM('2'!$Q$13:$Q$17),SUM('2'!$Q$15:$Q$18),SUM('2'!$Q$16:$Q$20),SUM('2'!$Q$17:$Q$21),SUM('2'!$Q$18:$Q$22),SUM('2'!$Q$20:$Q$23))) -> #REF! | H11: =CHOOSE($O$10,SUM('2'!$G$10:$G$13),SUM('2'!$G$11:$G$15),SUM('2'!$G$12:$G$16),SUM('2'!$G$13:$G$17),SUM('2'!$G$15:$G$18),SUM('2'!$G$16:$G$20),SUM('2'!$G$17:$G$21),SUM('2'!$G$18:$G$22),SUM('2'!$G$20:$G$23)) -> #REF! | I11: =IF(N11="","",H11/CHOOSE($O$10,SUM('2'!$Q$10:$Q$13),SUM('2'!$Q$11:$Q$15),SUM('2'!$Q$12:$Q$16),SUM('2'!$Q$13:$Q$17),SUM('2'!$Q$15:$Q$18),SUM('2'!$Q$16:$Q$20),SUM('2'!$Q$17:$Q$21),SUM('2'!$Q$18:$Q$22),SUM('2'!$Q$20:$Q$23))) -> #REF! | J11: =CHOOSE($O$10,SUM('2'!$H$10:$O$13),SUM('2'!$H$11:$O$15),SUM('2'!$H$12:$O$16),SUM('2'!$H$13:$O$17),SUM('2'!$H$15:$O$18),SUM('2'!$H$16:$O$20),SUM('2'!$H$17:$O$21),SUM('2'!$H$18:$O$22),SUM('2'!$H$20:$O$23)) -> #REF! | K11: =IF(N11="","",J11/CHOOSE($O$10,SUM('2'!$Q$10:$Q$13),SUM('2'!$Q$11:$Q$15),SUM('2'!$Q$12:$Q$16),SUM('2'!$Q$13:$Q$17),SUM('2'!$Q$15:$Q$18),SUM('2'!$Q$16:$Q$20),SUM('2'!$Q$17:$Q$21),SUM('2'!$Q$18:$Q$22),SUM('2'!$Q$20:$Q$23))) -> #REF! | L11: =CHOOSE($O$10,SUM('2'!$P$10:$P$13),SUM('2'!$P$11:$P$15),SUM('2'!$P$12:$P$16),SUM('2'!$P$13:$P$17),SUM('2'!$P$15:$P$18),SUM('2'!$P$16:$P$20),SUM('2'!$P$17:$P$21),SUM('2'!$P$18:$P$22),SUM('2'!$P$20:$P$23)) -> #REF! | M11: =IF(N11="","",L11/CHOOSE($O$10,SUM('2'!$Q$10:$Q$13),SUM('2'!$Q$11:$Q$15),SUM('2'!$Q$12:$Q$16),SUM('2'!$Q$13:$Q$17),SUM('2'!$Q$15:$Q$18),SUM('2'!$Q$16:$Q$20),SUM('2'!$Q$17:$Q$21),SUM('2'!$Q$18:$Q$22),SUM('2'!$Q$20:$Q$23))) -> #REF! | N11: =IF(B11+D11+F11+H11+J11+L11=0,"",B11+D11+F11+H11+J11+L11) -> #REF! | P11: =N11 -> #REF! | Q11: =IF(N11="","",MAX('2'!$R$10:$R$23)) -> #REF! | R11: =IF(SUM(D11,F11,J11)=0,"",SUM(D11,F11,J11)/N11) -> #REF!
A12: 3 | B12: =CHOOSE($O$10,SUM('3'!$C$10:$C$13,'3'!$D$10:$D$13),SUM('3'!$C$11:$C$15,'3'!$D$11:$D$15),SUM('3'!$C$12:$C$16,'3'!$D$12:$D$16),SUM('3'!$C$13:$C$17,'3'!$D$13:$D$17),SUM('3'!$C$15:$C$18,'3'!$D$15:$D$18),SUM('3'!$C$16:$C$20,'3'!$D$16:$D$20),SUM('3'!$C$17:$C$21,'3'!$D$17:$D$21),SUM('3'!$C$18:$C$22,'3'!$D$18:$D$22),SUM('3'!$C$20:$C$23,'3'!$D$20:$D$23)) -> #REF! | C12: =IF(N12="","",B12/CHOOSE($O$10,SUM('3'!$Q$10:$Q$13),SUM('3'!$Q$11:$Q$15),SUM('3'!$Q$12:$Q$16),SUM('3'!$Q$13:$Q$17),SUM('3'!$Q$15:$Q$18),SUM('3'!$Q$16:$Q$20),SUM('3'!$Q$17:$Q$21),SUM('3'!$Q$18:$Q$22),SUM('3'!$Q$20:$Q$23))) -> #REF! | D12: =CHOOSE($O$10,SUM('3'!$E$10:$E$13),SUM('3'!$E$11:$E$15),SUM('3'!$E$12:$E$16),SUM('3'!$E$13:$E$17),SUM('3'!$E$15:$E$18),SUM('3'!$E$16:$E$20),SUM('3'!$E$17:$E$21),SUM('3'!$E$18:$E$22),SUM('3'!$E$20:$E$23)) -> #REF! | E12: =IF(N12="","",D12/CHOOSE($O$10,SUM('3'!$Q$10:$Q$13),SUM('3'!$Q$11:$Q$15),SUM('3'!$Q$12:$Q$16),SUM('3'!$Q$13:$Q$17),SUM('3'!$Q$15:$Q$18),SUM('3'!$Q$16:$Q$20),SUM('3'!$Q$17:$Q$21),SUM('3'!$Q$18:$Q$22),SUM('3'!$Q$20:$Q$23))) -> #REF! | F12: =CHOOSE($O$10,SUM('3'!$F$10:$F$13),SUM('3'!$F$11:$F$15),SUM('3'!$F$12:$F$16),SUM('3'!$F$13:$F$17),SUM('3'!$F$15:$F$18),SUM('3'!$F$16:$F$20),SUM('3'!$F$17:$F$21),SUM('3'!$F$18:$F$22),SUM('3'!$F$20:$F$23)) -> #REF! | G12: =IF(N12="","",F12/CHOOSE($O$10,SUM('3'!$Q$10:$Q$13),SUM('3'!$Q$11:$Q$15),SUM('3'!$Q$12:$Q$16),SUM('3'!$Q$13:$Q$17),SUM('3'!$Q$15:$Q$18),SUM('3'!$Q$16:$Q$20),SUM('3'!$Q$17:$Q$21),SUM('3'!$Q$18:$Q$22),SUM('3'!$Q$20:$Q$23))) -> #REF! | H12: =CHOOSE($O$10,SUM('3'!$G$10:$G$13),SUM('3'!$G$11:$G$15),SUM('3'!$G$12:$G$16),SUM('3'!$G$13:$G$17),SUM('3'!$G$15:$G$18),SUM('3'!$G$16:$G$20),SUM('3'!$G$17:$G$21),SUM('3'!$G$18:$G$22),SUM('3'!$G$20:$G$23)) -> #REF! | I12: =IF(N12="","",H12/CHOOSE($O$10,SUM('3'!$Q$10:$Q$13),SUM('3'!$Q$11:$Q$15),SUM('3'!$Q$12:$Q$16),SUM('3'!$Q$13:$Q$17),SUM('3'!$Q$15:$Q$18),SUM('3'!$Q$16:$Q$20),SUM('3'!$Q$17:$Q$21),SUM('3'!$Q$18:$Q$22),SUM('3'!$Q$20:$Q$23))) -> #REF! | J12: =CHOOSE($O$10,SUM('3'!$H$10:$O$13),SUM('3'!$H$11:$O$15),SUM('3'!$H$12:$O$16),SUM('3'!$H$13:$O$17),SUM('3'!$H$15:$O$18),SUM('3'!$H$16:$O$20),SUM('3'!$H$17:$O$21),SUM('3'!$H$18:$O$22),SUM('3'!$H$20:$O$23)) -> #REF! | K12: =IF(N12="","",J12/CHOOSE($O$10,SUM('3'!$Q$10:$Q$13),SUM('3'!$Q$11:$Q$15),SUM('3'!$Q$12:$Q$16),SUM('3'!$Q$13:$Q$17),SUM('3'!$Q$15:$Q$18),SUM('3'!$Q$16:$Q$20),SUM('3'!$Q$17:$Q$21),SUM('3'!$Q$18:$Q$22),SUM('3'!$Q$20:$Q$23))) -> #REF! | L12: =CHOOSE($O$10,SUM('3'!$P$10:$P$13),SUM('3'!$P$11:$P$15),SUM('3'!$P$12:$P$16),SUM('3'!$P$13:$P$17),SUM('3'!$P$15:$P$18),SUM('3'!$P$16:$P$20),SUM('3'!$P$17:$P$21),SUM('3'!$P$18:$P$22),SUM('3'!$P$20:$P$23)) -> #REF! | M12: =IF(N12="","",L12/CHOOSE($O$10,SUM('3'!$Q$10:$Q$13),SUM('3'!$Q$11:$Q$15),SUM('3'!$Q$12:$Q$16),SUM('3'!$Q$13:$Q$17),SUM('3'!$Q$15:$Q$18),SUM('3'!$Q$16:$Q$20),SUM('3'!$Q$17:$Q$21),SUM('3'!$Q$18:$Q$22),SUM('3'!$Q$20:$Q$23))) -> #REF! | N12: =IF(B12+D12+F12+H12+J12+L12=0,"",B12+D12+F12+H12+J12+L12) -> #REF! | P12: =N12 -> #REF! | Q12: =IF(N12="","",MAX('3'!$R$10:$R$23)) -> #REF! | R12: =IF(SUM(D12,F12,J12)=0,"",SUM(D12,F12,J12)/N12) -> #REF!
A13: 4 | B13: =CHOOSE($O$10,SUM('4'!$C$10:$C$13,'4'!$D$10:$D$13),SUM('4'!$C$11:$C$15,'4'!$D$11:$D$15),SUM('4'!$C$12:$C$16,'4'!$D$12:$D$16),SUM('4'!$C$13:$C$17,'4'!$D$13:$D$17),SUM('4'!$C$15:$C$18,'4'!$D$15:$D$18),SUM('4'!$C$16:$C$20,'4'!$D$16:$D$20),SUM('4'!$C$17:$C$21,'4'!$D$17:$D$21),SUM('4'!$C$18:$C$22,'4'!$D$18:$D$22),SUM('4'!$C$20:$C$23,'4'!$D$20:$D$23)) -> #REF! | C13: =IF(N13="","",B13/CHOOSE($O$10,SUM('4'!$Q$10:$Q$13),SUM('4'!$Q$11:$Q$15),SUM('4'!$Q$12:$Q$16),SUM('4'!$Q$13:$Q$17),SUM('4'!$Q$15:$Q$18),SUM('4'!$Q$16:$Q$20),SUM('4'!$Q$17:$Q$21),SUM('4'!$Q$18:$Q$22),SUM('4'!$Q$20:$Q$23))) -> #REF! | D13: =CHOOSE($O$10,SUM('4'!$E$10:$E$13),SUM('4'!$E$11:$E$15),SUM('4'!$E$12:$E$16),SUM('4'!$E$13:$E$17),SUM('4'!$E$15:$E$18),SUM('4'!$E$16:$E$20),SUM('4'!$E$17:$E$21),SUM('4'!$E$18:$E$22),SUM('4'!$E$20:$E$23)) -> #REF! | E13: =IF(N13="","",D13/CHOOSE($O$10,SUM('4'!$Q$10:$Q$13),SUM('4'!$Q$11:$Q$15),SUM('4'!$Q$12:$Q$16),SUM('4'!$Q$13:$Q$17),SUM('4'!$Q$15:$Q$18),SUM('4'!$Q$16:$Q$20),SUM('4'!$Q$17:$Q$21),SUM('4'!$Q$18:$Q$22),SUM('4'!$Q$20:$Q$23))) -> #REF! | F13: =CHOOSE($O$10,SUM('4'!$F$10:$F$13),SUM('4'!$F$11:$F$15),SUM('4'!$F$12:$F$16),SUM('4'!$F$13:$F$17),SUM('4'!$F$15:$F$18),SUM('4'!$F$16:$F$20),SUM('4'!$F$17:$F$21),SUM('4'!$F$18:$F$22),SUM('4'!$F$20:$F$23)) -> #REF! | G13: =IF(N13="","",F13/CHOOSE($O$10,SUM('4'!$Q$10:$Q$13),SUM('4'!$Q$11:$Q$15),SUM('4'!$Q$12:$Q$16),SUM('4'!$Q$13:$Q$17),SUM('4'!$Q$15:$Q$18),SUM('4'!$Q$16:$Q$20),SUM('4'!$Q$17:$Q$21),SUM('4'!$Q$18:$Q$22),SUM('4'!$Q$20:$Q$23))) -> #REF! | H13: =CHOOSE($O$10,SUM('4'!$G$10:$G$13),SUM('4'!$G$11:$G$15),SUM('4'!$G$12:$G$16),SUM('4'!$G$13:$G$17),SUM('4'!$G$15:$G$18),SUM('4'!$G$16:$G$20),SUM('4'!$G$17:$G$21),SUM('4'!$G$18:$G$22),SUM('4'!$G$20:$G$23)) -> #REF! | I13: =IF(N13="","",H13/CHOOSE($O$10,SUM('4'!$Q$10:$Q$13),SUM('4'!$Q$11:$Q$15),SUM('4'!$Q$12:$Q$16),SUM('4'!$Q$13:$Q$17),SUM('4'!$Q$15:$Q$18),SUM('4'!$Q$16:$Q$20),SUM('4'!$Q$17:$Q$21),SUM('4'!$Q$18:$Q$22),SUM('4'!$Q$20:$Q$23))) -> #REF! | J13: =CHOOSE($O$10,SUM('4'!$H$10:$O$13),SUM('4'!$H$11:$O$15),SUM('4'!$H$12:$O$16),SUM('4'!$H$13:$O$17),SUM('4'!$H$15:$O$18),SUM('4'!$H$16:$O$20),SUM('4'!$H$17:$O$21),SUM('4'!$H$18:$O$22),SUM('4'!$H$20:$O$23)) -> #REF! | K13: =IF(N13="","",J13/CHOOSE($O$10,SUM('4'!$Q$10:$Q$13),SUM('4'!$Q$11:$Q$15),SUM('4'!$Q$12:$Q$16),SUM('4'!$Q$13:$Q$17),SUM('4'!$Q$15:$Q$18),SUM('4'!$Q$16:$Q$20),SUM('4'!$Q$17:$Q$21),SUM('4'!$Q$18:$Q$22),SUM('4'!$Q$20:$Q$23))) -> #REF! | L13: =CHOOSE($O$10,SUM('4'!$P$10:$P$13),SUM('4'!$P$11:$P$15),SUM('4'!$P$12:$P$16),SUM('4'!$P$13:$P$17),SUM('4'!$P$15:$P$18),SUM('4'!$P$16:$P$20),SUM('4'!$P$17:$P$21),SUM('4'!$P$18:$P$22),SUM('4'!$P$20:$P$23)) -> #REF! | M13: =IF(N13="","",L13/CHOOSE($O$10,SUM('4'!$Q$10:$Q$13),SUM('4'!$Q$11:$Q$15),SUM('4'!$Q$12:$Q$16),SUM('4'!$Q$13:$Q$17),SUM('4'!$Q$15:$Q$18),SUM('4'!$Q$16:$Q$20),SUM('4'!$Q$17:$Q$21),SUM('4'!$Q$18:$Q$22),SUM('4'!$Q$20:$Q$23))) -> #REF! | N13: =IF(B13+D13+F13+H13+J13+L13=0,"",B13+D13+F13+H13+J13+L13) -> #REF! | P13: =N13 -> #REF! | Q13: =IF(N13="","",MAX('4'!$R$10:$R$23)) -> #REF! | R13: =IF(SUM(D13,F13,J13)=0,"",SUM(D13,F13,J13)/N13) -> #REF!
A14: 5 | B14: =CHOOSE($O$10,SUM('5'!$C$10:$C$13,'5'!$D$10:$D$13),SUM('5'!$C$11:$C$15,'5'!$D$11:$D$15),SUM('5'!$C$12:$C$16,'5'!$D$12:$D$16),SUM('5'!$C$13:$C$17,'5'!$D$13:$D$17),SUM('5'!$C$15:$C$18,'5'!$D$15:$D$18),SUM('5'!$C$16:$C$20,'5'!$D$16:$D$20),SUM('5'!$C$17:$C$21,'5'!$D$17:$D$21),SUM('5'!$C$18:$C$22,'5'!$D$18:$D$22),SUM('5'!$C$20:$C$23,'5'!$D$20:$D$23)) -> #REF! | C14: =IF(N14="","",B14/CHOOSE($O$10,SUM('5'!$Q$10:$Q$13),SUM('5'!$Q$11:$Q$15),SUM('5'!$Q$12:$Q$16),SUM('5'!$Q$13:$Q$17),SUM('5'!$Q$15:$Q$18),SUM('5'!$Q$16:$Q$20),SUM('5'!$Q$17:$Q$21),SUM('5'!$Q$18:$Q$22),SUM('5'!$Q$20:$Q$23))) -> #REF! | D14: =CHOOSE($O$10,SUM('5'!$E$10:$E$13),SUM('5'!$E$11:$E$15),SUM('5'!$E$12:$E$16),SUM('5'!$E$13:$E$17),SUM('5'!$E$15:$E$18),SUM('5'!$E$16:$E$20),SUM('5'!$E$17:$E$21),SUM('5'!$E$18:$E$22),SUM('5'!$E$20:$E$23)) -> #REF! | E14: =IF(N14="","",D14/CHOOSE($O$10,SUM('5'!$Q$10:$Q$13),SUM('5'!$Q$11:$Q$15),SUM('5'!$Q$12:$Q$16),SUM('5'!$Q$13:$Q$17),SUM('5'!$Q$15:$Q$18),SUM('5'!$Q$16:$Q$20),SUM('5'!$Q$17:$Q$21),SUM('5'!$Q$18:$Q$22),SUM('5'!$Q$20:$Q$23))) -> #REF! | F14: =CHOOSE($O$10,SUM('5'!$F$10:$F$13),SUM('5'!$F$11:$F$15),SUM('5'!$F$12:$F$16),SUM('5'!$F$13:$F$17),SUM('5'!$F$15:$F$18),SUM('5'!$F$16:$F$20),SUM('5'!$F$17:$F$21),SUM('5'!$F$18:$F$22),SUM('5'!$F$20:$F$23)) -> #REF! | G14: =IF(N14="","",F14/CHOOSE($O$10,SUM('5'!$Q$10:$Q$13),SUM('5'!$Q$11:$Q$15),SUM('5'!$Q$12:$Q$16),SUM('5'!$Q$13:$Q$17),SUM('5'!$Q$15:$Q$18),SUM('5'!$Q$16:$Q$20),SUM('5'!$Q$17:$Q$21),SUM('5'!$Q$18:$Q$22),SUM('5'!$Q$20:$Q$23))) -> #REF! | H14: =CHOOSE($O$10,SUM('5'!$G$10:$G$13),SUM('5'!$G$11:$G$15),SUM('5'!$G$12:$G$16),SUM('5'!$G$13:$G$17),SUM('5'!$G$15:$G$18),SUM('5'!$G$16:$G$20),SUM('5'!$G$17:$G$21),SUM('5'!$G$18:$G$22),SUM('5'!$G$20:$G$23)) -> #REF! | I14: =IF(N14="","",H14/CHOOSE($O$10,SUM('5'!$Q$10:$Q$13),SUM('5'!$Q$11:$Q$15),SUM('5'!$Q$12:$Q$16),SUM('5'!$Q$13:$Q$17),SUM('5'!$Q$15:$Q$18),SUM('5'!$Q$16:$Q$20),SUM('5'!$Q$17:$Q$21),SUM('5'!$Q$18:$Q$22),SUM('5'!$Q$20:$Q$23))) -> #REF! | J14: =CHOOSE($O$10,SUM('5'!$H$10:$O$13),SUM('5'!$H$11:$O$15),SUM('5'!$H$12:$O$16),SUM('5'!$H$13:$O$17),SUM('5'!$H$15:$O$18),SUM('5'!$H$16:$O$20),SUM('5'!$H$17:$O$21),SUM('5'!$H$18:$O$22),SUM('5'!$H$20:$O$23)) -> #REF! | K14: =IF(N14="","",J14/CHOOSE($O$10,SUM('5'!$Q$10:$Q$13),SUM('5'!$Q$11:$Q$15),SUM('5'!$Q$12:$Q$16),SUM('5'!$Q$13:$Q$17),SUM('5'!$Q$15:$Q$18),SUM('5'!$Q$16:$Q$20),SUM('5'!$Q$17:$Q$21),SUM('5'!$Q$18:$Q$22),SUM('5'!$Q$20:$Q$23))) -> #REF! | L14: =CHOOSE($O$10,SUM('5'!$P$10:$P$13),SUM('5'!$P$11:$P$15),SUM('5'!$P$12:$P$16),SUM('5'!$P$13:$P$17),SUM('5'!$P$15:$P$18),SUM('5'!$P$16:$P$20),SUM('5'!$P$17:$P$21),SUM('5'!$P$18:$P$22),SUM('5'!$P$20:$P$23)) -> #REF! | M14: =IF(N14="","",L14/CHOOSE($O$10,SUM('5'!$Q$10:$Q$13),SUM('5'!$Q$11:$Q$15),SUM('5'!$Q$12:$Q$16),SUM('5'!$Q$13:$Q$17),SUM('5'!$Q$15:$Q$18),SUM('5'!$Q$16:$Q$20),SUM('5'!$Q$17:$Q$21),SUM('5'!$Q$18:$Q$22),SUM('5'!$Q$20:$Q$23))) -> #REF! | N14: =IF(B14+D14+F14+H14+J14+L14=0,"",B14+D14+F14+H14+J14+L14) -> #REF! | P14: =N14 -> #REF! | Q14: =IF(N14="","",MAX('5'!$R$10:$R$23)) -> #REF! | R14: =IF(SUM(D14,F14,J14)=0,"",SUM(D14,F14,J14)/N14) -> #REF!
A15: 6 | B15: =CHOOSE($O$10,SUM('6'!$C$10:$C$13,'6'!$D$10:$D$13),SUM('6'!$C$11:$C$15,'6'!$D$11:$D$15),SUM('6'!$C$12:$C$16,'6'!$D$12:$D$16),SUM('6'!$C$13:$C$17,'6'!$D$13:$D$17),SUM('6'!$C$15:$C$18,'6'!$D$15:$D$18),SUM('6'!$C$16:$C$20,'6'!$D$16:$D$20),SUM('6'!$C$17:$C$21,'6'!$D$17:$D$21),SUM('6'!$C$18:$C$22,'6'!$D$18:$D$22),SUM('6'!$C$20:$C$23,'6'!$D$20:$D$23)) -> #REF! | C15: =IF(N15="","",B15/CHOOSE($O$10,SUM('6'!$Q$10:$Q$13),SUM('6'!$Q$11:$Q$15),SUM('6'!$Q$12:$Q$16),SUM('6'!$Q$13:$Q$17),SUM('6'!$Q$15:$Q$18),SUM('6'!$Q$16:$Q$20),SUM('6'!$Q$17:$Q$21),SUM('6'!$Q$18:$Q$22),SUM('6'!$Q$20:$Q$23))) -> #REF! | D15: =CHOOSE($O$10,SUM('6'!$E$10:$E$13),SUM('6'!$E$11:$E$15),SUM('6'!$E$12:$E$16),SUM('6'!$E$13:$E$17),SUM('6'!$E$15:$E$18),SUM('6'!$E$16:$E$20),SUM('6'!$E$17:$E$21),SUM('6'!$E$18:$E$22),SUM('6'!$E$20:$E$23)) -> #REF! | E15: =IF(N15="","",D15/CHOOSE($O$10,SUM('6'!$Q$10:$Q$13),SUM('6'!$Q$11:$Q$15),SUM('6'!$Q$12:$Q$16),SUM('6'!$Q$13:$Q$17),SUM('6'!$Q$15:$Q$18),SUM('6'!$Q$16:$Q$20),SUM('6'!$Q$17:$Q$21),SUM('6'!$Q$18:$Q$22),SUM('6'!$Q$20:$Q$23))) -> #REF! | F15: =CHOOSE($O$10,SUM('6'!$F$10:$F$13),SUM('6'!$F$11:$F$15),SUM('6'!$F$12:$F$16),SUM('6'!$F$13:$F$17),SUM('6'!$F$15:$F$18),SUM('6'!$F$16:$F$20),SUM('6'!$F$17:$F$21),SUM('6'!$F$18:$F$22),SUM('6'!$F$20:$F$23)) -> #REF! | G15: =IF(N15="","",F15/CHOOSE($O$10,SUM('6'!$Q$10:$Q$13),SUM('6'!$Q$11:$Q$15),SUM('6'!$Q$12:$Q$16),SUM('6'!$Q$13:$Q$17),SUM('6'!$Q$15:$Q$18),SUM('6'!$Q$16:$Q$20),SUM('6'!$Q$17:$Q$21),SUM('6'!$Q$18:$Q$22),SUM('6'!$Q$20:$Q$23))) -> #REF! | H15: =CHOOSE($O$10,SUM('6'!$G$10:$G$13),SUM('6'!$G$11:$G$15),SUM('6'!$G$12:$G$16),SUM('6'!$G$13:$G$17),SUM('6'!$G$15:$G$18),SUM('6'!$G$16:$G$20),SUM('6'!$G$17:$G$21),SUM('6'!$G$18:$G$22),SUM('6'!$G$20:$G$23)) -> #REF! | I15: =IF(N15="","",H15/CHOOSE($O$10,SUM('6'!$Q$10:$Q$13),SUM('6'!$Q$11:$Q$15),SUM('6'!$Q$12:$Q$16),SUM('6'!$Q$13:$Q$17),SUM('6'!$Q$15:$Q$18),SUM('6'!$Q$16:$Q$20),SUM('6'!$Q$17:$Q$21),SUM('6'!$Q$18:$Q$22),SUM('6'!$Q$20:$Q$23))) -> #REF! | J15: =CHOOSE($O$10,SUM('6'!$H$10:$O$13),SUM('6'!$H$11:$O$15),SUM('6'!$H$12:$O$16),SUM('6'!$H$13:$O$17),SUM('6'!$H$15:$O$18),SUM('6'!$H$16:$O$20),SUM('6'!$H$17:$O$21),SUM('6'!$H$18:$O$22),SUM('6'!$H$20:$O$23)) -> #REF! | K15: =IF(N15="","",J15/CHOOSE($O$10,SUM('6'!$Q$10:$Q$13),SUM('6'!$Q$11:$Q$15),SUM('6'!$Q$12:$Q$16),SUM('6'!$Q$13:$Q$17),SUM('6'!$Q$15:$Q$18),SUM('6'!$Q$16:$Q$20),SUM('6'!$Q$17:$Q$21),SUM('6'!$Q$18:$Q$22),SUM('6'!$Q$20:$Q$23))) -> #REF! | L15: =CHOOSE($O$10,SUM('6'!$P$10:$P$13),SUM('6'!$P$11:$P$15),SUM('6'!$P$12:$P$16),SUM('6'!$P$13:$P$17),SUM('6'!$P$15:$P$18),SUM('6'!$P$16:$P$20),SUM('6'!$P$17:$P$21),SUM('6'!$P$18:$P$22),SUM('6'!$P$20:$P$23)) -> #REF! | M15: =IF(N15="","",L15/CHOOSE($O$10,SUM('6'!$Q$10:$Q$13),SUM('6'!$Q$11:$Q$15),SUM('6'!$Q$12:$Q$16),SUM('6'!$Q$13:$Q$17),SUM('6'!$Q$15:$Q$18),SUM('6'!$Q$16:$Q$20),SUM('6'!$Q$17:$Q$21),SUM('6'!$Q$18:$Q$22),SUM('6'!$Q$20:$Q$23))) -> #REF! | N15: =IF(B15+D15+F15+H15+J15+L15=0,"",B15+D15+F15+H15+J15+L15) -> #REF! | P15: =N15 -> #REF! | Q15: =IF(N15="","",MAX('6'!$R$10:$R$23)) -> #REF! | R15: =IF(SUM(D15,F15,J15)=0,"",SUM(D15,F15,J15)/N15) -> #REF!
A16: 7 | B16: =CHOOSE($O$10,SUM('7'!$C$10:$C$13,'7'!$D$10:$D$13),SUM('7'!$C$11:$C$15,'7'!$D$11:$D$15),SUM('7'!$C$12:$C$16,'7'!$D$12:$D$16),SUM('7'!$C$13:$C$17,'7'!$D$13:$D$17),SUM('7'!$C$15:$C$18,'7'!$D$15:$D$18),SUM('7'!$C$16:$C$20,'7'!$D$16:$D$20),SUM('7'!$C$17:$C$21,'7'!$D$17:$D$21),SUM('7'!$C$18:$C$22,'7'!$D$18:$D$22),SUM('7'!$C$20:$C$23,'7'!$D$20:$D$23)) -> #REF! | C16: =IF(N16="","",B16/CHOOSE($O$10,SUM('7'!$Q$10:$Q$13),SUM('7'!$Q$11:$Q$15),SUM('7'!$Q$12:$Q$16),SUM('7'!$Q$13:$Q$17),SUM('7'!$Q$15:$Q$18),SUM('7'!$Q$16:$Q$20),SUM('7'!$Q$17:$Q$21),SUM('7'!$Q$18:$Q$22),SUM('7'!$Q$20:$Q$23))) -> #REF! | D16: =CHOOSE($O$10,SUM('7'!$E$10:$E$13),SUM('7'!$E$11:$E$15),SUM('7'!$E$12:$E$16),SUM('7'!$E$13:$E$17),SUM('7'!$E$15:$E$18),SUM('7'!$E$16:$E$20),SUM('7'!$E$17:$E$21),SUM('7'!$E$18:$E$22),SUM('7'!$E$20:$E$23)) -> #REF! | E16: =IF(N16="","",D16/CHOOSE($O$10,SUM('7'!$Q$10:$Q$13),SUM('7'!$Q$11:$Q$15),SUM('7'!$Q$12:$Q$16),SUM('7'!$Q$13:$Q$17),SUM('7'!$Q$15:$Q$18),SUM('7'!$Q$16:$Q$20),SUM('7'!$Q$17:$Q$21),SUM('7'!$Q$18:$Q$22),SUM('7'!$Q$20:$Q$23))) -> #REF! | F16: =CHOOSE($O$10,SUM('7'!$F$10:$F$13),SUM('7'!$F$11:$F$15),SUM('7'!$F$12:$F$16),SUM('7'!$F$13:$F$17),SUM('7'!$F$15:$F$18),SUM('7'!$F$16:$F$20),SUM('7'!$F$17:$F$21),SUM('7'!$F$18:$F$22),SUM('7'!$F$20:$F$23)) -> #REF! | G16: =IF(N16="","",F16/CHOOSE($O$10,SUM('7'!$Q$10:$Q$13),SUM('7'!$Q$11:$Q$15),SUM('7'!$Q$12:$Q$16),SUM('7'!$Q$13:$Q$17),SUM('7'!$Q$15:$Q$18),SUM('7'!$Q$16:$Q$20),SUM('7'!$Q$17:$Q$21),SUM('7'!$Q$18:$Q$22),SUM('7'!$Q$20:$Q$23))) -> #REF! | H16: =CHOOSE($O$10,SUM('7'!$G$10:$G$13),SUM('7'!$G$11:$G$15),SUM('7'!$G$12:$G$16),SUM('7'!$G$13:$G$17),SUM('7'!$G$15:$G$18),SUM('7'!$G$16:$G$20),SUM('7'!$G$17:$G$21),SUM('7'!$G$18:$G$22),SUM('7'!$G$20:$G$23)) -> #REF! | I16: =IF(N16="","",H16/CHOOSE($O$10,SUM('7'!$Q$10:$Q$13),SUM('7'!$Q$11:$Q$15),SUM('7'!$Q$12:$Q$16),SUM('7'!$Q$13:$Q$17),SUM('7'!$Q$15:$Q$18),SUM('7'!$Q$16:$Q$20),SUM('7'!$Q$17:$Q$21),SUM('7'!$Q$18:$Q$22),SUM('7'!$Q$20:$Q$23))) -> #REF! | J16: =CHOOSE($O$10,SUM('7'!$H$10:$O$13),SUM('7'!$H$11:$O$15),SUM('7'!$H$12:$O$16),SUM('7'!$H$13:$O$17),SUM('7'!$H$15:$O$18),SUM('7'!$H$16:$O$20),SUM('7'!$H$17:$O$21),SUM('7'!$H$18:$O$22),SUM('7'!$H$20:$O$23)) -> #REF! | K16: =IF(N16="","",J16/CHOOSE($O$10,SUM('7'!$Q$10:$Q$13),SUM('7'!$Q$11:$Q$15),SUM('7'!$Q$12:$Q$16),SUM('7'!$Q$13:$Q$17),SUM('7'!$Q$15:$Q$18),SUM('7'!$Q$16:$Q$20),SUM('7'!$Q$17:$Q$21),SUM('7'!$Q$18:$Q$22),SUM('7'!$Q$20:$Q$23))) -> #REF! | L16: =CHOOSE($O$10,SUM('7'!$P$10:$P$13),SUM('7'!$P$11:$P$15),SUM('7'!$P$12:$P$16),SUM('7'!$P$13:$P$17),SUM('7'!$P$15:$P$18),SUM('7'!$P$16:$P$20),SUM('7'!$P$17:$P$21),SUM('7'!$P$18:$P$22),SUM('7'!$P$20:$P$23)) -> #REF! | M16: =IF(N16="","",L16/CHOOSE($O$10,SUM('7'!$Q$10:$Q$13),SUM('7'!$Q$11:$Q$15),SUM('7'!$Q$12:$Q$16),SUM('7'!$Q$13:$Q$17),SUM('7'!$Q$15:$Q$18),SUM('7'!$Q$16:$Q$20),SUM('7'!$Q$17:$Q$21),SUM('7'!$Q$18:$Q$22),SUM('7'!$Q$20:$Q$23))) -> #REF! | N16: =IF(B16+D16+F16+H16+J16+L16=0,"",B16+D16+F16+H16+J16+L16) -> #REF! | P16: =N16 -> #REF! | Q16: =IF(N16="","",MAX('7'!$R$10:$R$23)) -> #REF! | R16: =IF(SUM(D16,F16,J16)=0,"",SUM(D16,F16,J16)/N16) -> #REF!
